Workbook

Sheet Bilogito
A2: Consideraremos los últimos 30 años de información históricas de las TEF(años 1990-2019)
A4: Paso 1:
A5: Tasas Específicas de Fecundidad
A7: Edad / Año | B7: 1990 | C7: 1991 | D7: 1992 | E7: 1993 | F7: 1994 | G7: 1995 | H7: 1996 | I7: 1997 | J7: 1998 | K7: 1999 | L7: 2000 | M7: 2001 | N7: 2002 | O7: 2003 | P7: 2004 | Q7: 2005 | R7: 2006 | S7: 2007 | T7: 2008 | U7: 2009 | V7: 2010 | W7: 2011 | X7: 2012 | Y7: 2013 | Z7: 2014 | AA7: 2015 | AB7: 2016 | AC7: 2017 | AD7: 2018 | AE7: 2019
A8: 15-19 | B8: 0.09023316 | C8: 0.08979424 | D8: 0.08932138 | E8: 0.08859282 | F8: 0.08766908 | G8: 0.08677621 | H8: 0.08609792 | I8: 0.08556392 | J8: 0.08498493 | K8: 0.08427989 | L8: 0.08349368 | M8: 0.08261784 | N8: 0.08165239 | O8: 0.08057568 | P8: 0.07951613 | Q8: 0.07866721 | R8: 0.0781937 | S8: 0.07811569 | T8: 0.07832146 | U8: 0.07853459 | V8: 0.07851286 | W8: 0.07811843 | X8: 0.07731792 | Y8: 0.0761322 | Z8: 0.07449598 | AA8: 0.07238167 | AB8: 0.06984584 | AC8: 0.06796853 | AD8: 0.06677473 | AE8: 0.06510769
A9: 20-24 | B9: 0.19252694 | C9: 0.18921925 | D9: 0.18490077 | E9: 0.18028378 | F9: 0.17554268 | G9: 0.17052035 | H9: 0.1658955 | I9: 0.16256274 | J9: 0.16123892 | K9: 0.16084347 | L9: 0.15935642 | M9: 0.15632101 | N9: 0.15253087 | O9: 0.14862856 | P9: 0.14550888 | Q9: 0.14303838 | R9: 0.1415167 | S9: 0.1407791 | T9: 0.14025658 | U9: 0.13938419 | V9: 0.13760848 | W9: 0.13467939 | X9: 0.13128821 | Y9: 0.1284531 | Z9: 0.12598377 | AA9: 0.12279641 | AB9: 0.11835452 | AC9: 0.11431439 | AD9: 0.11174587 | AE9: 0.10918104
A10: 25-29 | B10: 0.18786406 | C10: 0.18361131 | D10: 0.17843484 | E10: 0.17291133 | F10: 0.16773778 | G10: 0.16233992 | H10: 0.15729666 | I10: 0.15299309 | J10: 0.15003626 | K10: 0.14878475 | L10: 0.14676963 | M10: 0.14358071 | N10: 0.13925581 | O10: 0.13553115 | P10: 0.13289515 | Q10: 0.13106013 | R10: 0.12938509 | S10: 0.12747225 | T10: 0.12534487 | U10: 0.12293889 | V10: 0.1199081 | W10: 0.11661816 | X10: 0.11323161 | Y10: 0.11083061 | Z10: 0.10937845 | AA10: 0.10808481 | AB10: 0.10631725 | AC10: 0.10479963 | AD10: 0.10434263 | AE10: 0.10335688
A11: 30-34 | B11: 0.13976904 | C11: 0.13612701 | D11: 0.13245527 | E11: 0.1281178 | F11: 0.12291038 | G11: 0.11778294 | H11: 0.1124164 | I11: 0.10854243 | J11: 0.10639692 | K11: 0.10530112 | L11: 0.10363379 | M11: 0.10123952 | N11: 0.0987826 | O11: 0.09697878 | P11: 0.0956492 | Q11: 0.09409987 | R11: 0.09231686 | S11: 0.09041309 | T11: 0.08850897 | U11: 0.08637259 | V11: 0.08377685 | W11: 0.08125763 | X11: 0.07898553 | Y11: 0.07764304 | Z11: 0.07660369 | AA11: 0.0757819 | AB11: 0.07440186 | AC11: 0.07363489 | AD11: 0.07404502 | AE11: 0.07459631
A12: 35-39 | B12: 0.08509774 | C12: 0.08158901 | D12: 0.07779617 | E12: 0.0735229 | F12: 0.06941181 | G12: 0.06615753 | H12: 0.0635762 | I12: 0.06148906 | J12: 0.0598245 | K12: 0.05796869 | L12: 0.05583352 | M12: 0.05342551 | N12: 0.05104825 | O12: 0.04930388 | P12: 0.04800861 | Q12: 0.04717849 | R12: 0.04646381 | S12: 0.04580895 | T12: 0.04476403 | U12: 0.04333734 | V12: 0.04171267 | W12: 0.04024485 | X12: 0.03922929 | Y12: 0.03872453 | Z12: 0.03816502 | AA12: 0.03742746 | AB12: 0.03667245 | AC12: 0.03674568 | AD12: 0.03801536 | AE12: 0.03981781
A13: 40-44 | B13: 0.0304127 | C13: 0.02927691 | D13: 0.02822933 | E13: 0.02715302 | F13: 0.02593926 | G13: 0.0246199 | H13: 0.02329545 | I13: 0.02203625 | J13: 0.02081984 | K13: 0.01961677 | L13: 0.01849934 | M13: 0.01753568 | N13: 0.01671752 | O13: 0.01592369 | P13: 0.01511031 | Q13: 0.01432927 | R13: 0.01360875 | S13: 0.01294798 | T13: 0.01233668 | U13: 0.01176726 | V13: 0.01128652 | W13: 0.0109169 | X13: 0.01061137 | Y13: 0.01033281 | Z13: 0.01008408 | AA13: 0.00989097 | AB13: 0.00973493 | AC13: 0.00975029 | AD13: 0.0099845 | AE13: 0.01046752
A14: 45-49 | B14: 0.00663231 | C14: 0.00621261 | D14: 0.00582913 | E14: 0.00545396 | F14: 0.00507862 | G14: 0.00472149 | H14: 0.00438328 | I14: 0.00405361 | J14: 0.003716 | K14: 0.00337078 | L14: 0.00304746 | M14: 0.0027755 | N14: 0.00254005 | O14: 0.00231713 | P14: 0.0021162 | Q14: 0.00196466 | R14: 0.00184923 | S14: 0.00173315 | T14: 0.0015968 | U14: 0.00144317 | V14: 0.0012984 | W14: 0.0011786 | X14: 0.0010668 | Y14: 0.00095497 | Z14: 0.00086313 | AA14: 0.00081659 | AB14: 0.00080794 | AC14: 0.00082534 | AD14: 0.00087845 | AE14: 0.00101865
A16: Paso 2:
A17: Tasas Específicas de Fecundidad del patrón estándar
A19: Edad / Año | B19: Patrón estándar
A20: 15-19 | B20: =AVERAGE(B8:AE8) -> 0.079988592
A21: 20-24 | B21: =AVERAGE(B9:AE9) -> 0.14817534
A22: 25-29 | B22: =AVERAGE(B10:AE10) -> 0.13643706
A23: 30-34 | B23: =AVERAGE(B11:AE11) -> 0.097618043
A24: 35-39 | B24: =AVERAGE(B12:AE12) -> 0.052278704
A25: 40-44 | B25: =AVERAGE(B13:AE13) -> 0.016774527
A26: 45-49 | B26: =AVERAGE(B14:AE14) -> 0.0026848003
A28: Paso 3:
A29: Tasa Global de Fecundidad
A31: Año | B31: 1990 | C31: 1991 | D31: 1992 | E31: 1993 | F31: 1994 | G31: 1995 | H31: 1996 | I31: 1997 | J31: 1998 | K31: 1999 | L31: 2000 | M31: 2001 | N31: 2002 | O31: 2003 | P31: 2004 | Q31: 2005 | R31: 2006 | S31: 2007 | T31: 2008 | U31: 2009 | V31: 2010 | W31: 2011 | X31: 2012 | Y31: 2013 | Z31: 2014 | AA31: 2015 | AB31: 2016 | AC31: 2017 | AD31: 2018 | AE31: 2019
A32: TGF | B32: =5*SUM(B8:B14) -> 3.6626798 | C32: =5*SUM(C8:C14) -> 3.5791517 | D32: =5*SUM(D8:D14) -> 3.4848345 | E32: =5*SUM(E8:E14) -> 3.3801781 | F32: =5*SUM(F8:F14) -> 3.2714481 | G32: =5*SUM(G8:G14) -> 3.1645917 | H32: =5*SUM(H8:H14) -> 3.064807 | I32: =5*SUM(I8:I14) -> 2.9862055 | ... AE32: =5*SUM(AE8:AE14) -> 2.0177295
A33: TGF patrón estándar | B33: =AVERAGE(B32:AE32) -> 2.6697853
A35: Paso 4:
A36: Descendencias parciales (F(x))
A38: Edad / Año | B38: 1990 | C38: 1991 | D38: 1992 | E38: 1993 | F38: 1994 | G38: 1995 | H38: 1996 | I38: 1997 | J38: 1998 | K38: 1999 | L38: 2000 | M38: 2001 | N38: 2002 | O38: 2003 | P38: 2004 | Q38: 2005 | R38: 2006 | S38: 2007 | T38: 2008 | U38: 2009 | V38: 2010 | W38: 2011 | X38: 2012 | Y38: 2013 | Z38: 2014 | AA38: 2015 | AB38: 2016 | AC38: 2017 | AD38: 2018 | AE38: 2019
A39: 15-19
A40: 20-24 | B40: =5*B8 -> 0.4511658 | C40: =5*C8 -> 0.4489712 | D40: =5*D8 -> 0.4466069 | E40: =5*E8 -> 0.4429641 | F40: =5*F8 -> 0.4383454 | G40: =5*G8 -> 0.43388105 | H40: =5*H8 -> 0.4304896 | I40: =5*I8 -> 0.4278196 | ... AE40: =5*AE8 -> 0.32553845
A41: 25-29 | B41: =5*B9+B40 -> 1.4138005 | C41: =5*C9+C40 -> 1.3950674 | D41: =5*D9+D40 -> 1.3711108 | E41: =5*E9+E40 -> 1.344383 | F41: =5*F9+F40 -> 1.3160588 | G41: =5*G9+G40 -> 1.2864828 | H41: =5*H9+H40 -> 1.2599671 | I41: =5*I9+I40 -> 1.2406333 | ... AE41: =5*AE9+AE40 -> 0.87144365
A42: 30-34 | B42: =5*B10+B41 -> 2.3531208 | C42: =5*C10+C41 -> 2.313124 | D42: =5*D10+D41 -> 2.263285 | E42: =5*E10+E41 -> 2.2089397 | F42: =5*F10+F41 -> 2.1547477 | G42: =5*G10+G41 -> 2.0981824 | H42: =5*H10+H41 -> 2.0464504 | I42: =5*I10+I41 -> 2.0055987 | ... AE42: =5*AE10+AE41 -> 1.388228
A43: 35-39 | B43: =5*B11+B42 -> 3.051966 | C43: =5*C11+C42 -> 2.9937591 | D43: =5*D11+D42 -> 2.9255613 | E43: =5*E11+E42 -> 2.8495286 | F43: =5*F11+F42 -> 2.7692996 | G43: =5*G11+G42 -> 2.6870971 | H43: =5*H11+H42 -> 2.6085324 | I43: =5*I11+I42 -> 2.5483109 | ... AE43: =5*AE11+AE42 -> 1.7612096
A44: 40-44 | B44: =5*B12+B43 -> 3.4774547 | C44: =5*C12+C43 -> 3.4017041 | D44: =5*D12+D43 -> 3.3145421 | E44: =5*E12+E43 -> 3.2171432 | F44: =5*F12+F43 -> 3.1163586 | G44: =5*G12+G43 -> 3.0178847 | H44: =5*H12+H43 -> 2.9264134 | I44: =5*I12+I43 -> 2.8557562 | ... AE44: =5*AE12+AE43 -> 1.9602986
A45: 45-49 | B45: =5*B13+B44 -> 3.6295182 | C45: =5*C13+C44 -> 3.5480887 | D45: =5*D13+D44 -> 3.4556888 | E45: =5*E13+E44 -> 3.3529083 | F45: =5*F13+F44 -> 3.2460549 | G45: =5*G13+G44 -> 3.1409842 | H45: =5*H13+H44 -> 3.0428906 | I45: =5*I13+I44 -> 2.9659374 | ... AE45: =5*AE13+AE44 -> 2.0126362
A46: TGF | B46: =B32 -> 3.6626798 | C46: =C32 -> 3.5791517 | D46: =D32 -> 3.4848345 | E46: =E32 -> 3.3801781 | F46: =F32 -> 3.2714481 | G46: =G32 -> 3.1645917 | H46: =H32 -> 3.064807 | I46: =I32 -> 2.9862055 | ... AE46: =AE32 -> 2.0177295
A49: Proporción de la fecundidad global hasta la edad x (F(x)/TGF)
A51: Edad / Año | B51: 1990 | C51: 1991 | D51: 1992 | E51: 1993 | F51: 1994 | G51: 1995 | H51: 1996 | I51: 1997 | J51: 1998 | K51: 1999 | L51: 2000 | M51: 2001 | N51: 2002 | O51: 2003 | P51: 2004 | Q51: 2005 | R51: 2006 | S51: 2007 | T51: 2008 | U51: 2009 | V51: 2010 | W51: 2011 | X51: 2012 | Y51: 2013 | Z51: 2014 | AA51: 2015 | AB51: 2016 | AC51: 2017 | AD51: 2018 | AE51: 2019
A52: 15-19
...

Sheet Bilogito-valores
A2: Consideraremos los últimos 30 años de información históricas de las TEF(años 1990-2019)
A4: Paso 1:
A5: Tasas Específicas de Fecundidad
A7: Edad / Año | B7: 1990 | C7: 1991 | D7: 1992 | E7: 1993 | F7: 1994 | G7: 1995 | H7: 1996 | I7: 1997 | J7: 1998 | K7: 1999 | L7: 2000 | M7: 2001 | N7: 2002 | O7: 2003 | P7: 2004 | Q7: 2005 | R7: 2006 | S7: 2007 | T7: 2008 | U7: 2009 | V7: 2010 | W7: 2011 | X7: 2012 | Y7: 2013 | Z7: 2014 | AA7: 2015 | AB7: 2016 | AC7: 2017 | AD7: 2018 | AE7: 2019
A8: 15-19 | B8: 0.09023316 | C8: 0.08979424 | D8: 0.08932138 | E8: 0.08859282 | F8: 0.08766908 | G8: 0.08677621 | H8: 0.08609792 | I8: 0.08556392 | J8: 0.08498493 | K8: 0.08427989 | L8: 0.08349368 | M8: 0.08261784 | N8: 0.08165239 | O8: 0.08057568 | P8: 0.07951613 | Q8: 0.07866721 | R8: 0.0781937 | S8: 0.07811569 | T8: 0.07832146 | U8: 0.07853459 | V8: 0.07851286 | W8: 0.07811843 | X8: 0.07731792 | Y8: 0.0761322 | Z8: 0.07449598 | AA8: 0.07238167 | AB8: 0.06984584 | AC8: 0.06796853 | AD8: 0.06677473 | AE8: 0.06510769
A9: 20-24 | B9: 0.19252694 | C9: 0.18921925 | D9: 0.18490077 | E9: 0.18028378 | F9: 0.17554268 | G9: 0.17052035 | H9: 0.1658955 | I9: 0.16256274 | J9: 0.16123892 | K9: 0.16084347 | L9: 0.15935642 | M9: 0.15632101 | N9: 0.15253087 | O9: 0.14862856 | P9: 0.14550888 | Q9: 0.14303838 | R9: 0.1415167 | S9: 0.1407791 | T9: 0.14025658 | U9: 0.13938419 | V9: 0.13760848 | W9: 0.13467939 | X9: 0.13128821 | Y9: 0.1284531 | Z9: 0.12598377 | AA9: 0.12279641 | AB9: 0.11835452 | AC9: 0.11431439 | AD9: 0.11174587 | AE9: 0.10918104
A10: 25-29 | B10: 0.18786406 | C10: 0.18361131 | D10: 0.17843484 | E10: 0.17291133 | F10: 0.16773778 | G10: 0.16233992 | H10: 0.15729666 | I10: 0.15299309 | J10: 0.15003626 | K10: 0.14878475 | L10: 0.14676963 | M10: 0.14358071 | N10: 0.13925581 | O10: 0.13553115 | P10: 0.13289515 | Q10: 0.13106013 | R10: 0.12938509 | S10: 0.12747225 | T10: 0.12534487 | U10: 0.12293889 | V10: 0.1199081 | W10: 0.11661816 | X10: 0.11323161 | Y10: 0.11083061 | Z10: 0.10937845 | AA10: 0.10808481 | AB10: 0.10631725 | AC10: 0.10479963 | AD10: 0.10434263 | AE10: 0.10335688
A11: 30-34 | B11: 0.13976904 | C11: 0.13612701 | D11: 0.13245527 | E11: 0.1281178 | F11: 0.12291038 | G11: 0.11778294 | H11: 0.1124164 | I11: 0.10854243 | J11: 0.10639692 | K11: 0.10530112 | L11: 0.10363379 | M11: 0.10123952 | N11: 0.0987826 | O11: 0.09697878 | P11: 0.0956492 | Q11: 0.09409987 | R11: 0.09231686 | S11: 0.09041309 | T11: 0.08850897 | U11: 0.08637259 | V11: 0.08377685 | W11: 0.08125763 | X11: 0.07898553 | Y11: 0.07764304 | Z11: 0.07660369 | AA11: 0.0757819 | AB11: 0.07440186 | AC11: 0.07363489 | AD11: 0.07404502 | AE11: 0.07459631
A12: 35-39 | B12: 0.08509774 | C12: 0.08158901 | D12: 0.07779617 | E12: 0.0735229 | F12: 0.06941181 | G12: 0.06615753 | H12: 0.0635762 | I12: 0.06148906 | J12: 0.0598245 | K12: 0.05796869 | L12: 0.05583352 | M12: 0.05342551 | N12: 0.05104825 | O12: 0.04930388 | P12: 0.04800861 | Q12: 0.04717849 | R12: 0.04646381 | S12: 0.04580895 | T12: 0.04476403 | U12: 0.04333734 | V12: 0.04171267 | W12: 0.04024485 | X12: 0.03922929 | Y12: 0.03872453 | Z12: 0.03816502 | AA12: 0.03742746 | AB12: 0.03667245 | AC12: 0.03674568 | AD12: 0.03801536 | AE12: 0.03981781
A13: 40-44 | B13: 0.0304127 | C13: 0.02927691 | D13: 0.02822933 | E13: 0.02715302 | F13: 0.02593926 | G13: 0.0246199 | H13: 0.02329545 | I13: 0.02203625 | J13: 0.02081984 | K13: 0.01961677 | L13: 0.01849934 | M13: 0.01753568 | N13: 0.01671752 | O13: 0.01592369 | P13: 0.01511031 | Q13: 0.01432927 | R13: 0.01360875 | S13: 0.01294798 | T13: 0.01233668 | U13: 0.01176726 | V13: 0.01128652 | W13: 0.0109169 | X13: 0.01061137 | Y13: 0.01033281 | Z13: 0.01008408 | AA13: 0.00989097 | AB13: 0.00973493 | AC13: 0.00975029 | AD13: 0.0099845 | AE13: 0.01046752
A14: 45-49 | B14: 0.00663231 | C14: 0.00621261 | D14: 0.00582913 | E14: 0.00545396 | F14: 0.00507862 | G14: 0.00472149 | H14: 0.00438328 | I14: 0.00405361 | J14: 0.003716 | K14: 0.00337078 | L14: 0.00304746 | M14: 0.0027755 | N14: 0.00254005 | O14: 0.00231713 | P14: 0.0021162 | Q14: 0.00196466 | R14: 0.00184923 | S14: 0.00173315 | T14: 0.0015968 | U14: 0.00144317 | V14: 0.0012984 | W14: 0.0011786 | X14: 0.0010668 | Y14: 0.00095497 | Z14: 0.00086313 | AA14: 0.00081659 | AB14: 0.00080794 | AC14: 0.00082534 | AD14: 0.00087845 | AE14: 0.00101865
A16: Paso 2:
A17: Tasas Específicas de Fecundidad del patrón estándar
A19: Edad / Año | B19: Patrón estándar
A20: 15-19 | B20: 0.079988592
A21: 20-24 | B21: 0.14817534
A22: 25-29 | B22: 0.13643706
A23: 30-34 | B23: 0.097618043
A24: 35-39 | B24: 0.052278704
A25: 40-44 | B25: 0.016774527
A26: 45-49 | B26: 0.0026848003
A28: Paso 3:
A29: Tasa Global de Fecundidad
A31: Año | B31: 1990 | C31: 1991 | D31: 1992 | E31: 1993 | F31: 1994 | G31: 1995 | H31: 1996 | I31: 1997 | J31: 1998 | K31: 1999 | L31: 2000 | M31: 2001 | N31: 2002 | O31: 2003 | P31: 2004 | Q31: 2005 | R31: 2006 | S31: 2007 | T31: 2008 | U31: 2009 | V31: 2010 | W31: 2011 | X31: 2012 | Y31: 2013 | Z31: 2014 | AA31: 2015 | AB31: 2016 | AC31: 2017 | AD31: 2018 | AE31: 2019
A32: TGF | B32: 3.6626798 | C32: 3.5791517 | D32: 3.4848345 | E32: 3.3801781 | F32: 3.2714481 | G32: 3.1645917 | H32: 3.064807 | I32: 2.9862055 | J32: 2.9350869 | K32: 2.9008273 | L32: 2.8531692 | M32: 2.7874789 | N32: 2.7126374 | O32: 2.6462944 | P32: 2.5940224 | Q32: 2.55169 | R32: 2.5166707 | S32: 2.4863511 | T32: 2.455647 | U32: 2.4188901 | V32: 2.3705194 | W32: 2.3150698 | X32: 2.2586536 | Y32: 2.2153563 | Z32: 2.1778706 | AA32: 2.135899 | AB32: 2.0806739 | AC32: 2.0401938 | AD32: 2.0289328 | AE32: 2.0177295
A33: TGF patrón estándar | B33: 2.6697853
A35: Paso 4:
A36: Descendencias parciales (F(x))
A38: Edad / Año | B38: 1990 | C38: 1991 | D38: 1992 | E38: 1993 | F38: 1994 | G38: 1995 | H38: 1996 | I38: 1997 | J38: 1998 | K38: 1999 | L38: 2000 | M38: 2001 | N38: 2002 | O38: 2003 | P38: 2004 | Q38: 2005 | R38: 2006 | S38: 2007 | T38: 2008 | U38: 2009 | V38: 2010 | W38: 2011 | X38: 2012 | Y38: 2013 | Z38: 2014 | AA38: 2015 | AB38: 2016 | AC38: 2017 | AD38: 2018 | AE38: 2019
A39: 15-19
A40: 20-24 | B40: 0.4511658 | C40: 0.4489712 | D40: 0.4466069 | E40: 0.4429641 | F40: 0.4383454 | G40: 0.43388105 | H40: 0.4304896 | I40: 0.4278196 | J40: 0.42492465 | K40: 0.42139945 | L40: 0.4174684 | M40: 0.4130892 | N40: 0.40826195 | O40: 0.4028784 | P40: 0.39758065 | Q40: 0.39333605 | R40: 0.3909685 | S40: 0.39057845 | T40: 0.3916073 | U40: 0.39267295 | V40: 0.3925643 | W40: 0.39059215 | X40: 0.3865896 | Y40: 0.380661 | Z40: 0.3724799 | AA40: 0.36190835 | AB40: 0.3492292 | AC40: 0.33984265 | AD40: 0.33387365 | AE40: 0.32553845
A41: 25-29 | B41: 1.4138005 | C41: 1.3950674 | D41: 1.3711107 | E41: 1.344383 | F41: 1.3160588 | G41: 1.2864828 | H41: 1.2599671 | I41: 1.2406333 | J41: 1.2311193 | K41: 1.2256168 | L41: 1.2142505 | M41: 1.1946942 | N41: 1.1709163 | O41: 1.1460212 | P41: 1.1251251 | Q41: 1.108528 | R41: 1.098552 | S41: 1.094474 | T41: 1.0928902 | U41: 1.0895939 | V41: 1.0806067 | W41: 1.0639891 | X41: 1.0430306 | Y41: 1.0229265 | Z41: 1.0023988 | AA41: 0.9758904 | AB41: 0.9410018 | AC41: 0.9114146 | AD41: 0.892603 | AE41: 0.87144365
A42: 30-34 | B42: 2.3531208 | C42: 2.313124 | D42: 2.263285 | E42: 2.2089397 | F42: 2.1547477 | G42: 2.0981824 | H42: 2.0464504 | I42: 2.0055987 | J42: 1.9813006 | K42: 1.9695405 | L42: 1.9480987 | M42: 1.9125978 | N42: 1.8671953 | O42: 1.8236769 | P42: 1.7896008 | Q42: 1.7638286 | R42: 1.7454775 | S42: 1.7318352 | T42: 1.7196145 | U42: 1.7042884 | V42: 1.6801472 | W42: 1.6470799 | X42: 1.6091887 | Y42: 1.5770795 | Z42: 1.549291 | AA42: 1.5163144 | AB42: 1.472588 | AC42: 1.4354128 | AD42: 1.4143162 | AE42: 1.388228
A43: 35-39 | B43: 3.051966 | C43: 2.993759 | D43: 2.9255613 | E43: 2.8495287 | F43: 2.7692996 | G43: 2.6870971 | H43: 2.6085324 | I43: 2.5483109 | J43: 2.5132852 | K43: 2.4960461 | L43: 2.4662676 | M43: 2.4187954 | N43: 2.3611083 | O43: 2.3085708 | P43: 2.2678468 | Q43: 2.2343279 | R43: 2.2070618 | S43: 2.1839006 | T43: 2.1621594 | U43: 2.1361513 | V43: 2.0990315 | W43: 2.0533681 | X43: 2.0041163 | Y43: 1.9652947 | Z43: 1.9323095 | AA43: 1.8952239 | AB43: 1.8445973 | AC43: 1.8035872 | AD43: 1.7845413 | AE43: 1.7612096
A44: 40-44 | B44: 3.4774547 | C44: 3.4017041 | D44: 3.3145422 | E44: 3.2171432 | F44: 3.1163587 | G44: 3.0178847 | H44: 2.9264134 | I44: 2.8557562 | J44: 2.8124077 | K44: 2.7858896 | L44: 2.7454352 | M44: 2.6859229 | N44: 2.6163496 | O44: 2.5550903 | P44: 2.5078899 | Q44: 2.4702204 | R44: 2.4393808 | S44: 2.4129454 | T44: 2.3859796 | U44: 2.352838 | V44: 2.3075948 | W44: 2.2545923 | X44: 2.2002628 | Y44: 2.1589174 | Z44: 2.1231346 | AA44: 2.0823612 | AB44: 2.0279596 | AC44: 1.9873156 | AD44: 1.9746181 | AE44: 1.9602986
A45: 45-49 | B45: 3.6295182 | C45: 3.5480886 | D45: 3.4556888 | E45: 3.3529083 | F45: 3.246055 | G45: 3.1409843 | H45: 3.0428906 | I45: 2.9659374 | J45: 2.9165069 | K45: 2.8839734 | L45: 2.8379319 | M45: 2.7736013 | N45: 2.6999372 | O45: 2.6347087 | P45: 2.5834414 | Q45: 2.5418668 | R45: 2.5074245 | S45: 2.4776853 | T45: 2.4476629 | U45: 2.4116743 | V45: 2.3640274 | W45: 2.3091768 | X45: 2.2533196 | Y45: 2.2105814 | Z45: 2.173555 | AA45: 2.1318161 | AB45: 2.0766342 | AC45: 2.0360671 | AD45: 2.0245406 | AE45: 2.0126362
A46: TGF | B46: 3.6626798 | C46: 3.5791517 | D46: 3.4848345 | E46: 3.3801781 | F46: 3.2714481 | G46: 3.1645917 | H46: 3.064807 | I46: 2.9862055 | J46: 2.9350869 | K46: 2.9008273 | L46: 2.8531692 | M46: 2.7874789 | N46: 2.7126374 | O46: 2.6462944 | P46: 2.5940224 | Q46: 2.55169 | R46: 2.5166707 | S46: 2.4863511 | T46: 2.455647 | U46: 2.4188901 | V46: 2.3705194 | W46: 2.3150698 | X46: 2.2586536 | Y46: 2.2153563 | Z46: 2.1778706 | AA46: 2.135899 | AB46: 2.0806739 | AC46: 2.0401938 | AD46: 2.0289328 | AE46: 2.0177295
A49: Proporción de la fecundidad global hasta la edad x (F(x)/TGF)
A51: Edad / Año | B51: 1990 | C51: 1991 | D51: 1992 | E51: 1993 | F51: 1994 | G51: 1995 | H51: 1996 | I51: 1997 | J51: 1998 | K51: 1999 | L51: 2000 | M51: 2001 | N51: 2002 | O51: 2003 | P51: 2004 | Q51: 2005 | R51: 2006 | S51: 2007 | T51: 2008 | U51: 2009 | V51: 2010 | W51: 2011 | X51: 2012 | Y51: 2013 | Z51: 2014 | AA51: 2015 | AB51: 2016 | AC51: 2017 | AD51: 2018 | AE51: 2019
A52: 15-19
...

Sheet Proyección TGF
A1: AÑO | B1: TGF
A2: {=TRANSPOSE('Bilogito-valores'!B178:AE178)} -> 1990 | B2: {=TRANSPOSE('Bilogito-valores'!B186:AE186)} -> 3.6626798
A3: 1991 | B3: 3.5791517
A4: 1992 | B4: 3.4848345
A5: 1993 | B5: 3.3801781
A6: 1994 | B6: 3.2714481
A7: 1995 | B7: 3.1645917
A8: 1996 | B8: 3.064807
A9: 1997 | B9: 2.9862055
A10: 1998 | B10: 2.9350869
A11: 1999 | B11: 2.9008273
A12: 2000 | B12: 2.8531692
A13: 2001 | B13: 2.7874789
A14: 2002 | B14: 2.7126375
... A82: 2070 | B82: 1.5061003

Sheet Proyección Bilogito
A4: Boligitos estándar
A6: Edad | B6: Estándar
A7: 15-19
A8: 20-24 | B8: =[1]Bilogito!B103 -> 0.64102797
A9: 25-29 | B9: =[1]Bilogito!B104 -> -0.16222361
A10: 30-34 | B10: =[1]Bilogito!B105 -> -0.96361337
A11: 35-39 | B11: =[1]Bilogito!B106 -> -1.9360233
A12: 40-44 | B12: =[1]Bilogito!B107 -> -3.2934842
A13: 45-49 | B13: =[1]Bilogito!B108 -> -5.2901897
A15: Proyección de a, b y TGF
A16: Bilogitos ajustados
A18: Edad / Año | B18: 2020 | C18: 2021 | D18: 2022 | E18: 2023 | F18: 2024 | G18: 2025 | H18: 2026 | I18: 2027 | J18: 2028 | K18: 2029 | L18: 2030 | M18: 2031 | N18: 2032 | O18: 2033 | P18: 2034 | Q18: 2035 | R18: 2036 | S18: 2037 | T18: 2038 | U18: 2039 | V18: 2040 | W18: 2041 | X18: 2042 | Y18: 2043 | Z18: 2044 | AA18: 2045 | AB18: 2046 | AC18: 2047 | AD18: 2048 | AE18: 2049 | AF18: 2050 | AG18: 2051 | AH18: 2052 | AI18: 2053 | AJ18: 2054 | AK18: 2055 | AL18: 2056 | AM18: 2057 | AN18: 2058 | AO18: 2059 | AP18: 2060 | AQ18: 2061 | AR18: 2062 | AS18: 2063 | AT18: 2064 | AU18: 2065 | AV18: 2066 | AW18: 2067 | AX18: 2068 | AY18: 2069 | AZ18: 2070
A19: a | B19: -0.090936622 | C19: -0.096375004 | D19: -0.10181339 | E19: -0.10725177 | F19: -0.11269015 | G19: -0.11812853 | H19: -0.12356691 | I19: -0.12900529 | J19: -0.13444367 | K19: -0.13988206 | L19: -0.14532044 | M19: -0.15075882 | N19: -0.1561972 | O19: -0.16163558 | P19: -0.16707396 | Q19: -0.17251234 | R19: -0.17795073 | S19: -0.18338911 | T19: -0.18882749 | U19: -0.19426587 | V19: -0.19970425 | W19: -0.20514263 | X19: -0.21058102 | Y19: -0.2160194 | Z19: -0.22145778 | AA19: -0.22689616 | AB19: -0.23233454 | AC19: -0.23777292 | AD19: -0.2432113 | AE19: -0.24864969 | AF19: -0.25408807 | AG19: -0.25952645 | AH19: -0.26496483 | AI19: -0.27040321 | AJ19: -0.27584159 | AK19: -0.28127997 | AL19: -0.28671836 | AM19: -0.29215674 | AN19: -0.29759512 | AO19: -0.3030335 | AP19: -0.30847188 | AQ19: -0.31391026 | AR19: -0.31934864 | AS19: -0.32478703 | AT19: -0.33022541 | AU19: -0.33566379 | AV19: -0.34110217 | AW19: -0.34654055 | AX19: -0.35197893 | AY19: -0.35741732 | AZ19: -0.3628557
A20: b | B20: 1.1538082 | C20: 1.161873 | D20: 1.1699378 | E20: 1.1780026 | F20: 1.1860674 | G20: 1.1941321 | H20: 1.2021969 | I20: 1.2102617 | J20: 1.2183265 | K20: 1.2263913 | L20: 1.2344561 | M20: 1.2425208 | N20: 1.2505856 | O20: 1.2586504 | P20: 1.2667152 | Q20: 1.27478 | R20: 1.2828448 | S20: 1.2909096 | T20: 1.2989743 | U20: 1.3070391 | V20: 1.3151039 | W20: 1.3231687 | X20: 1.3312335 | Y20: 1.3392983 | Z20: 1.347363 | AA20: 1.3554278 | AB20: 1.3634926 | AC20: 1.3715574 | AD20: 1.3796222 | AE20: 1.387687 | AF20: 1.3957518 | AG20: 1.4038165 | AH20: 1.4118813 | AI20: 1.4199461 | AJ20: 1.4280109 | AK20: 1.4360757 | AL20: 1.4441405 | AM20: 1.4522053 | AN20: 1.46027 | AO20: 1.4683348 | AP20: 1.4763996 | AQ20: 1.4844644 | AR20: 1.4925292 | AS20: 1.500594 | AT20: 1.5086587 | AU20: 1.5167235 | AV20: 1.5247883 | AW20: 1.5328531 | AX20: 1.5409179 | AY20: 1.5489827 | AZ20: 1.5570475
A21: TGF | B21: 1.9854682 | C21: 1.9425845 | D21: 1.9067112 | E21: 1.8812483 | F21: 1.8587871 | G21: 1.8334805 | H21: 1.806415 | I21: 1.7814243 | J21: 1.7599059 | K21: 1.7405418 | L21: 1.7218535 | M21: 1.7037267 | N21: 1.6868432 | O21: 1.6715592 | P21: 1.6576379 | Q21: 1.6447017 | R21: 1.6326118 | S21: 1.6214294 | T21: 1.6111947 | U21: 1.6018343 | V21: 1.5932288 | W21: 1.5852967 | X21: 1.5780038 | Y21: 1.5713232 | Z21: 1.5652104 | AA21: 1.5596112 | AB21: 1.554478 | AC21: 1.5497748 | AD21: 1.5454713 | AE21: 1.5415361 | AF21: 1.5379375 | AG21: 1.5346459 | AH21: 1.5316359 | AI21: 1.5288847 | AJ21: 1.5263707 | AK21: 1.5240739 | AL21: 1.5219756 | AM21: 1.5200586 | AN21: 1.5183078 | AO21: 1.5167089 | AP21: 1.515249 | AQ21: 1.5139161 | AR21: 1.5126991 | AS21: 1.5115881 | AT21: 1.5105739 | AU21: 1.5096483 | AV21: 1.5088034 | AW21: 1.5080323 | AX21: 1.5073285 | AY21: 1.5066863 | AZ21: 1.5061003
A24: Paso 9:
A25: Bilogitos ajustados
A27: Edad / Año | B27: 2020 | C27: 2021 | D27: 2022 | E27: 2023 | F27: 2024 | G27: 2025 | H27: 2026 | I27: 2027 | J27: 2028 | K27: 2029 | L27: 2030 | M27: 2031 | N27: 2032 | O27: 2033 | P27: 2034 | Q27: 2035 | R27: 2036 | S27: 2037 | T27: 2038 | U27: 2039 | V27: 2040 | W27: 2041 | X27: 2042 | Y27: 2043 | Z27: 2044 | AA27: 2045 | AB27: 2046 | AC27: 2047 | AD27: 2048 | AE27: 2049 | AF27: 2050 | AG27: 2051 | AH27: 2052 | AI27: 2053 | AJ27: 2054 | AK27: 2055 | AL27: 2056 | AM27: 2057 | AN27: 2058 | AO27: 2059 | AP27: 2060 | AQ27: 2061 | AR27: 2062 | AS27: 2063 | AT27: 2064 | AU27: 2065 | AV27: 2066 | AW27: 2067 | AX27: 2068 | AY27: 2069 | AZ27: 2070
A28: 15-19
A29: 20-24 | B29: =B$19+B$20*$B8 -> 0.64868672 | C29: =C$19+C$20*$B8 -> 0.64841809 | D29: =D$19+D$20*$B8 -> 0.64814946 | E29: =E$19+E$20*$B8 -> 0.64788083 | F29: =F$19+F$20*$B8 -> 0.6476122 | G29: =G$19+G$20*$B8 -> 0.64734357 | H29: =H$19+H$20*$B8 -> 0.64707494 | I29: =I$19+I$20*$B8 -> 0.64680631 | ... AZ29: =AZ$19+AZ$20*$B8 -> 0.63525528
A30: 25-29 | B30: =B$19+B$20*$B9 -> -0.27811156 | C30: =C$19+C$20*$B9 -> -0.28485824 | D30: =D$19+D$20*$B9 -> -0.29160492 | E30: =E$19+E$20*$B9 -> -0.2983516 | F30: =F$19+F$20*$B9 -> -0.30509828 | G30: =G$19+G$20*$B9 -> -0.31184496 | H30: =H$19+H$20*$B9 -> -0.31859164 | I30: =I$19+I$20*$B9 -> -0.32533832 | ... AZ30: =AZ$19+AZ$20*$B9 -> -0.61544556
A31: 30-34 | B31: =B$19+B$20*$B10 -> -1.2027616 | C31: =C$19+C$20*$B10 -> -1.2159714 | D31: =D$19+D$20*$B10 -> -1.2291811 | E31: =E$19+E$20*$B10 -> -1.2423908 | F31: =F$19+F$20*$B10 -> -1.2556005 | G31: =G$19+G$20*$B10 -> -1.2688102 | H31: =H$19+H$20*$B10 -> -1.2820199 | I31: =I$19+I$20*$B10 -> -1.2952296 | ... AZ31: =AZ$19+AZ$20*$B10 -> -1.8632474
A32: 35-39 | B32: =B$19+B$20*$B11 -> -2.3247362 | C32: =C$19+C$20*$B11 -> -2.3457882 | D32: =D$19+D$20*$B11 -> -2.3668402 | E32: =E$19+E$20*$B11 -> -2.3878922 | F32: =F$19+F$20*$B11 -> -2.4089442 | G32: =G$19+G$20*$B11 -> -2.4299962 | H32: =H$19+H$20*$B11 -> -2.4510482 | I32: =I$19+I$20*$B11 -> -2.4721002 | ... AZ32: =AZ$19+AZ$20*$B11 -> -3.3773359
A33: 40-44 | B33: =B$19+B$20*$B12 -> -3.8909858 | C33: =C$19+C$20*$B12 -> -3.9229854 | D33: =D$19+D$20*$B12 -> -3.954985 | E33: =E$19+E$20*$B12 -> -3.9869846 | F33: =F$19+F$20*$B12 -> -4.0189843 | G33: =G$19+G$20*$B12 -> -4.0509839 | H33: =H$19+H$20*$B12 -> -4.0829835 | I33: =I$19+I$20*$B12 -> -4.1149831 | ... AZ33: =AZ$19+AZ$20*$B12 -> -5.4909669
A34: 45-49 | B34: =B$19+B$20*$B13 -> -6.194801 | C34: =C$19+C$20*$B13 -> -6.2429036 | D34: =D$19+D$20*$B13 -> -6.2910062 | E34: =E$19+E$20*$B13 -> -6.3391088 | F34: =F$19+F$20*$B13 -> -6.3872115 | G34: =G$19+G$20*$B13 -> -6.4353141 | H34: =H$19+H$20*$B13 -> -6.4834167 | I34: =I$19+I$20*$B13 -> -6.5315193 | ... AZ34: =AZ$19+AZ$20*$B13 -> -8.5999322
A36: Paso 10:
A37: Estructuras porcentuales acumuladas ajustadas
A39: Edad / Año | B39: 2020 | C39: 2021 | D39: 2022 | E39: 2023 | F39: 2024 | G39: 2025 | H39: 2026 | I39: 2027 | J39: 2028 | K39: 2029 | L39: 2030 | M39: 2031 | N39: 2032 | O39: 2033 | P39: 2034 | Q39: 2035 | R39: 2036 | S39: 2037 | T39: 2038 | U39: 2039 | V39: 2040 | W39: 2041 | X39: 2042 | Y39: 2043 | Z39: 2044 | AA39: 2045 | AB39: 2046 | AC39: 2047 | AD39: 2048 | AE39: 2049 | AF39: 2050 | AG39: 2051 | AH39: 2052 | AI39: 2053 | AJ39: 2054 | AK39: 2055 | AL39: 2056 | AM39: 2057 | AN39: 2058 | AO39: 2059 | AP39: 2060 | AQ39: 2061 | AR39: 2062 | AS39: 2063 | AT39: 2064 | AU39: 2065 | AV39: 2066 | AW39: 2067 | AX39: 2068 | AY39: 2069 | AZ39: 2070
A40: 15-19
A41: 20-24 | B41: =EXP(-EXP(B29)) -> 0.14763285 | C41: =EXP(-EXP(C29)) -> 0.14770873 | D41: =EXP(-EXP(D29)) -> 0.14778462 | E41: =EXP(-EXP(E29)) -> 0.14786054 | F41: =EXP(-EXP(F29)) -> 0.14793647 | G41: =EXP(-EXP(G29)) -> 0.14801242 | H41: =EXP(-EXP(H29)) -> 0.14808839 | I41: =EXP(-EXP(I29)) -> 0.14816438 | ... AZ41: =EXP(-EXP(AZ29)) -> 0.15144937
A42: 25-29 | B42: =EXP(-EXP(B30)) -> 0.46897194 | C42: =EXP(-EXP(C30)) -> 0.47136579 | D42: =EXP(-EXP(D30)) -> 0.47375563 | E42: =EXP(-EXP(E30)) -> 0.47614141 | F42: =EXP(-EXP(F30)) -> 0.47852303 | G42: =EXP(-EXP(G30)) -> 0.48090043 | H42: =EXP(-EXP(H30)) -> 0.48327354 | I42: =EXP(-EXP(I30)) -> 0.48564229 | ... AZ42: =EXP(-EXP(AZ30)) -> 0.58251516
A43: 30-34 | B43: =EXP(-EXP(B31)) -> 0.74054893 | C43: =EXP(-EXP(C31)) -> 0.74347366 | D43: =EXP(-EXP(D31)) -> 0.74637133 | E43: =EXP(-EXP(E31)) -> 0.74924205 | F43: =EXP(-EXP(F31)) -> 0.75208592 | G43: =EXP(-EXP(G31)) -> 0.75490305 | H43: =EXP(-EXP(H31)) -> 0.75769356 | I43: =EXP(-EXP(I31)) -> 0.76045756 | ... AZ43: =EXP(-EXP(AZ31)) -> 0.85627139
A44: 35-39 | B44: =EXP(-EXP(B32)) -> 0.90682187 | C44: =EXP(-EXP(C32)) -> 0.90867146 | D44: =EXP(-EXP(D32)) -> 0.91048617 | E44: =EXP(-EXP(E32)) -> 0.91226658 | F44: =EXP(-EXP(F32)) -> 0.91401328 | G44: =EXP(-EXP(G32)) -> 0.91572684 | H44: =EXP(-EXP(H32)) -> 0.91740781 | I44: =EXP(-EXP(I32)) -> 0.91905675 | ... AZ44: =EXP(-EXP(AZ32)) -> 0.96643785
A45: 40-44 | B45: =EXP(-EXP(B33)) -> 0.97978198 | C45: =EXP(-EXP(C33)) -> 0.98041243 | D45: =EXP(-EXP(D33)) -> 0.98102341 | E45: =EXP(-EXP(E33)) -> 0.98161551 | F45: =EXP(-EXP(F33)) -> 0.98218931 | G45: =EXP(-EXP(G33)) -> 0.98274535 | H45: =EXP(-EXP(H33)) -> 0.98328419 | I45: =EXP(-EXP(I33)) -> 0.98380633 | ... AZ45: =EXP(-EXP(AZ33)) -> 0.99588464
A46: 45-49 | B46: =EXP(-EXP(B34)) -> 0.99796207 | C46: =EXP(-EXP(C34)) -> 0.99805769 | D46: =EXP(-EXP(D34)) -> 0.99814882 | E46: =EXP(-EXP(E34)) -> 0.99823568 | F46: =EXP(-EXP(F34)) -> 0.99831847 | G46: =EXP(-EXP(G34)) -> 0.99839738 | H46: =EXP(-EXP(H34)) -> 0.99847259 | I46: =EXP(-EXP(I34)) -> 0.99854427 | ... AZ46: =EXP(-EXP(AZ34)) -> 0.9998159
A48: Paso 11:
A49: Estructuras porcentuales desacumuladas ajustadas
A51: Edad / Año | B51: 2020 | C51: 2021 | D51: 2022 | E51: 2023 | F51: 2024 | G51: 2025 | H51: 2026 | I51: 2027 | J51: 2028 | K51: 2029 | L51: 2030 | M51: 2031 | N51: 2032 | O51: 2033 | P51: 2034 | Q51: 2035 | R51: 2036 | S51: 2037 | T51: 2038 | U51: 2039 | V51: 2040 | W51: 2041 | X51: 2042 | Y51: 2043 | Z51: 2044 | AA51: 2045 | AB51: 2046 | AC51: 2047 | AD51: 2048 | AE51: 2049 | AF51: 2050 | AG51: 2051 | AH51: 2052 | AI51: 2053 | AJ51: 2054 | AK51: 2055 | AL51: 2056 | AM51: 2057 | AN51: 2058 | AO51: 2059 | AP51: 2060 | AQ51: 2061 | AR51: 2062 | AS51: 2063 | AT51: 2064 | AU51: 2065 | AV51: 2066 | AW51: 2067 | AX51: 2068 | AY51: 2069 | AZ51: 2070
A52: 15-19 | B52: =B41 -> 0.14763285 | C52: =C41 -> 0.14770873 | D52: =D41 -> 0.14778462 | E52: =E41 -> 0.14786054 | F52: =F41 -> 0.14793647 | G52: =G41 -> 0.14801242 | H52: =H41 -> 0.14808839 | I52: =I41 -> 0.14816438 | ... AZ52: =AZ41 -> 0.15144937
A53: 20-24 | B53: =B42-B41 -> 0.32133909 | C53: =C42-C41 -> 0.32365706 | D53: =D42-D41 -> 0.32597101 | E53: =E42-E41 -> 0.32828087 | F53: =F42-F41 -> 0.33058656 | G53: =G42-G41 -> 0.33288801 | H53: =H42-H41 -> 0.33518515 | I53: =I42-I41 -> 0.33747791 | ... AZ53: =AZ42-AZ41 -> 0.43106579
...

Sheet CSV
A1: Año | B1: b | C1: a
A2: 1990 | B2: 0.92023851 | C2: 0.10685607 | E2: a | F2: -0.090936622 | G2: -0.096375004 | H2: -0.10181339 | I2: -0.10725177 | J2: -0.11269015 | K2: -0.11812853 | L2: -0.12356691 | M2: -0.12900529 | N2: -0.13444367 | O2: -0.13988206 | P2: -0.14532044 | Q2: -0.15075882 | R2: -0.1561972 | S2: -0.16163558 | T2: -0.16707396 | U2: -0.17251234 | V2: -0.17795073 | W2: -0.18338911 | X2: -0.18882749 | Y2: -0.19426587 | Z2: -0.19970425 | AA2: -0.20514263 | AB2: -0.21058102 | AC2: -0.2160194 | AD2: -0.22145778 | AE2: -0.22689616 | AF2: -0.23233454 | AG2: -0.23777292 | AH2: -0.2432113 | AI2: -0.24864969 | AJ2: -0.25408807 | AK2: -0.25952645 | AL2: -0.26496483 | AM2: -0.27040321 | AN2: -0.27584159 | AO2: -0.28127997 | AP2: -0.28671836 | AQ2: -0.29215674 | AR2: -0.29759512 | AS2: -0.3030335 | AT2: -0.30847188 | AU2: -0.31391026 | AV2: -0.31934864 | AW2: -0.32478703 | AX2: -0.33022541 | AY2: -0.33566379 | AZ2: -0.34110217 | BA2: -0.34654055 | BB2: -0.35197893 | BC2: -0.35741732 | BD2: -0.3628557
A3: 1991 | B3: 0.92536845 | C3: 0.096857123 | E3: b | F3: 1.1538082 | G3: 1.161873 | H3: 1.1699378 | I3: 1.1780026 | J3: 1.1860674 | K3: 1.1941321 | L3: 1.2021969 | M3: 1.2102617 | N3: 1.2183265 | O3: 1.2263913 | P3: 1.2344561 | Q3: 1.2425208 | R3: 1.2505856 | S3: 1.2586504 | T3: 1.2667152 | U3: 1.27478 | V3: 1.2828448 | W3: 1.2909096 | X3: 1.2989743 | Y3: 1.3070391 | Z3: 1.3151039 | AA3: 1.3231687 | AB3: 1.3312335 | AC3: 1.3392983 | AD3: 1.347363 | AE3: 1.3554278 | AF3: 1.3634926 | AG3: 1.3715574 | AH3: 1.3796222 | AI3: 1.387687 | AJ3: 1.3957518 | AK3: 1.4038165 | AL3: 1.4118813 | AM3: 1.4199461 | AN3: 1.4280109 | AO3: 1.4360757 | AP3: 1.4441405 | AQ3: 1.4522053 | AR3: 1.46027 | AS3: 1.4683348 | AT3: 1.4763996 | AU3: 1.4844644 | AV3: 1.4925292 | AW3: 1.500594 | AX3: 1.5086587 | AY3: 1.5167235 | AZ3: 1.5247883 | BA3: 1.5328531 | BB3: 1.5409179 | BC3: 1.5489827 | BD3: 1.5570475
A4: 1992 | B4: 0.92945232 | C4: 0.086941428
A5: 1993 | B5: 0.93310263 | C5: 0.075195773
A6: 1994 | B6: 0.93697926 | C6: 0.061796898
A7: 1995 | B7: 0.94120174 | C7: 0.049473366 | F7: 1.9854682 | G7: 1.9425845 | H7: 1.9067112 | I7: 1.8812483 | J7: 1.8587871 | K7: 1.8334805 | L7: 1.806415 | M7: 1.7814243 | N7: 1.7599059 | O7: 1.7405418 | P7: 1.7218535 | Q7: 1.7037267 | R7: 1.6868432 | S7: 1.6715592 | T7: 1.6576379 | U7: 1.6447017 | V7: 1.6326118 | W7: 1.6214294 | X7: 1.6111947 | Y7: 1.6018343 | Z7: 1.5932288 | AA7: 1.5852967 | AB7: 1.5780038 | AC7: 1.5713232 | AD7: 1.5652104 | AE7: 1.5596112 | AF7: 1.554478 | AG7: 1.5497748 | AH7: 1.5454713 | AI7: 1.5415361 | AJ7: 1.5379375 | AK7: 1.5346459 | AL7: 1.5316359 | AM7: 1.5288847 | AN7: 1.5263707 | AO7: 1.5240739 | AP7: 1.5219756 | AQ7: 1.5200586 | AR7: 1.5183078 | AS7: 1.5167089 | AT7: 1.515249 | AU7: 1.5139161 | AV7: 1.5126991 | AW7: 1.5115881 | AX7: 1.5105739 | AY7: 1.5096483 | AZ7: 1.5088034 | BA7: 1.5080323 | BB7: 1.5073285 | BC7: 1.5066863 | BD7: 1.5061003
A8: 1996 | B8: 0.94536545 | C8: 0.036095913
A9: 1997 | B9: 0.95196011 | C9: 0.024985626
A10: 1998 | B10: 0.96269221 | C10: 0.016987843
A11: 1999 | B11: 0.97738185 | C11: 0.011029413
A12: 2000 | B12: 0.99110012 | C12: 0.004311913
A13: 2001 | B13: 1.0016392 | C13: -0.0032771866
A14: 2002 | B14: 1.0101073 | C14: -0.010265292
A15: 2003 | B15: 1.0201245 | C15: -0.01302805
A16: 2004 | B16: 1.0317198 | C16: -0.013938564
A17: 2005 | B17: 1.0416154 | C17: -0.015747558
A18: 2006 | B18: 1.0494778 | C18: -0.020830525
A19: 2007 | B19: 1.0571477 | C19: -0.028900374
... A31: 2019 | B31: 1.0925145 | C31: -0.009225323
