Workbook

Sheet Pob_Mujeres
A1: Edad / Año | B1: 1950 | C1: 1951 | D1: 1952 | E1: 1953 | F1: 1954 | G1: 1955 | H1: 1956 | I1: 1957 | J1: 1958 | K1: 1959 | L1: 1960 | M1: 1961 | N1: 1962 | O1: 1963 | P1: 1964 | Q1: 1965 | R1: 1966 | S1: 1967 | T1: 1968 | U1: 1969 | V1: 1970 | W1: 1971 | X1: 1972 | Y1: 1973 | Z1: 1974 | AA1: 1975 | AB1: 1976 | AC1: 1977 | AD1: 1978 | AE1: 1979 | AF1: 1980 | AG1: 1981 | AH1: 1982 | AI1: 1983 | AJ1: 1984 | AK1: 1985 | AL1: 1986 | AM1: 1987 | AN1: 1988 | AO1: 1989 | AP1: 1990 | AQ1: 1991 | AR1: 1992 | AS1: 1993 | AT1: 1994 | AU1: 1995 | AV1: 1996 | AW1: 1997 | AX1: 1998 | AY1: 1999 | AZ1: 2000 | BA1: 2001 | BB1: 2002 | BC1: 2003 | BD1: 2004 | BE1: 2005 | BF1: 2006 | BG1: 2007 | BH1: 2008 | BI1: 2009 | BJ1: 2010 | BK1: 2011 | BL1: 2012 | BM1: 2013 | BN1: 2014 | BO1: 2015 | BP1: 2016 | BQ1: 2017 | BR1: 2018 | BS1: 2019 | BT1: 2020 | BU1: 2021 | BV1: 2022 | BW1: 2023 | BX1: 2024 | BY1: 2025 | BZ1: 2026 | CA1: 2027 | CB1: 2028 | CC1: 2029 | CD1: 2030 | CE1: 2031 | CF1: 2032 | CG1: 2033 | CH1: 2034 | CI1: 2035 | CJ1: 2036 | CK1: 2037 | CL1: 2038 | CM1: 2039 | CN1: 2040 | CO1: 2041 | CP1: 2042 | CQ1: 2043 | CR1: 2044 | CS1: 2045 | CT1: 2046 | CU1: 2047 | CV1: 2048 | CW1: 2049 | CX1: 2050 | CY1: 2051 | CZ1: 2052 | DA1: 2053 | DB1: 2054 | DC1: 2055 | DD1: 2056 | DE1: 2057 | DF1: 2058 | DG1: 2059 | DH1: 2060 | DI1: 2061 | DJ1: 2062 | DK1: 2063 | DL1: 2064 | DM1: 2065 | DN1: 2066 | DO1: 2067 | DP1: 2068 | DQ1: 2069 | DR1: 2070
A2: Nacimientos_mujeres | B2: =Fecundidad_quinq!B27 -> 624114.63 | C2: =Fecundidad_quinq!C27 -> 637542.44 | D2: =Fecundidad_quinq!D27 -> 656048.29 | E2: =Fecundidad_quinq!E27 -> 678082.93 | F2: =Fecundidad_quinq!F27 -> 701977.56 | G2: =Fecundidad_quinq!G27 -> 725233.17 | H2: =Fecundidad_quinq!H27 -> 745974.63 | I2: =Fecundidad_quinq!I27 -> 767729.27 | ... BT2: =Fecundidad_quinq!BT27 -> 0
A3: 0 | B3: 568159 | C3: 577657 | D3: 594071 | E3: 613919 | F3: 637887 | G3: 664331 | H3: 687186 | I3: 709353 | J3: 734135 | K3: 761687 | L3: 789861 | M3: 817039 | N3: 843057 | O3: 869110 | P3: 894980 | Q3: 918818 | R3: 940802 | S3: 963564 | T3: 988138 | U3: 1013052 | V3: 1035566 | W3: 1057292 | X3: 1079355 | Y3: 1098834 | Z3: 1113078 | AA3: 1120216 | AB3: 1119863 | AC3: 1114898 | AD3: 1110564 | AE3: 1109767 | AF3: 1112820 | AG3: 1118950 | AH3: 1127826 | AI3: 1138284 | AJ3: 1148996 | AK3: 1158565 | AL3: 1165584 | AM3: 1171628 | AN3: 1178909 | AO3: 1187825 | AP3: 1199002 | AQ3: 1211052 | AR3: 1218077 | AS3: 1217522 | AT3: 1211511 | AU3: 1201764 | AV3: 1190169 | AW3: 1180559 | AX3: 1177188 | AY3: 1179706 | AZ3: 1180786 | BA3: 1174619 | BB3: 1162310 | BC3: 1149001 | BD3: 1139422 | BE3: 1134996 | BF3: 1135595 | BG3: 1140270 | BH3: 1145414 | BI3: 1147389 | BJ3: 1143986 | BK3: 1134496 | BL3: 1120894 | BM3: 1108343 | BN3: 1098548 | BO3: 1086717 | BP3: 1068484 | BQ3: 1049485 | BR3: 1041110 | BS3: 1039522 | BT3: =BS2*nSx_Mujeres!BS2 -> 1034797.5 | BU3: =BT2*nSx_Mujeres!BT2 -> 0 | BV3: =BU2*nSx_Mujeres!BU2 -> 0 | BW3: =BV2*nSx_Mujeres!BV2 -> 0 | BX3: =BW2*nSx_Mujeres!BW2 -> 0 | BY3: =BX2*nSx_Mujeres!BX2 -> 0 | BZ3: =BY2*nSx_Mujeres!BY2 -> 0 | CA3: =BZ2*nSx_Mujeres!BZ2 -> 0 | ... DN3: =DM2*nSx_Mujeres!DM2 -> 0
A4: 1 | B4: 516674 | C4: 524131 | D4: 534601 | E4: 551292 | F4: 572190 | G4: 598676 | H4: 625741 | I4: 649509 | J4: 672357 | K4: 697516 | L4: 724941 | M4: 752809 | N4: 779936 | O4: 806067 | P4: 832251 | Q4: 858393 | R4: 882577 | S4: 904743 | T4: 927696 | U4: 952605 | V4: 976468 | W4: 999848 | X4: 1024410 | Y4: 1047745 | Z4: 1068275 | AA4: 1083771 | AB4: 1092545 | AC4: 1093888 | AD4: 1090524 | AE4: 1087948 | AF4: 1088866 | AG4: 1093255 | AH4: 1100399 | AI4: 1110168 | AJ4: 1121409 | AK4: 1132724 | AL4: 1142724 | AM4: 1150078 | AN4: 1156557 | AO4: 1163836 | AP4: 1172842 | AQ4: 1184891 | AR4: 1197655 | AS4: 1205123 | AT4: 1205093 | AU4: 1199621 | AV4: 1190310 | AW4: 1178902 | AX4: 1169301 | AY4: 1165685 | AZ4: 1168285 | BA4: 1170490 | BB4: 1165742 | BC4: 1154664 | BD4: 1142231 | BE4: 1134099 | BF4: 1131776 | BG4: 1134207 | BH4: 1138674 | BI4: 1142582 | BJ4: 1144191 | BK4: 1140449 | BL4: 1130337 | BM4: 1116372 | BN4: 1103314 | BO4: 1092467 | BP4: 1080174 | BQ4: 1062388 | BR4: 1044247 | BS4: 1036319 | BT4: =BS3*nSx_Mujeres!BS3 -> 1037454 | BU4: =BT3*nSx_Mujeres!BT3 -> 0 | BV4: =BU3*nSx_Mujeres!BU3 -> 0 | BW4: =BV3*nSx_Mujeres!BV3 -> 0 | BX4: =BW3*nSx_Mujeres!BW3 -> 0 | BY4: =BX3*nSx_Mujeres!BX3 -> 0 | BZ4: =BY3*nSx_Mujeres!BY3 -> 0 | CA4: =BZ3*nSx_Mujeres!BZ3 -> 0 | ... DN4: =DM3*nSx_Mujeres!DM3 -> 0
A5: 2 | B5: 483825 | C5: 492911 | D5: 501142 | E5: 512434 | F5: 529988 | G5: 552614 | H5: 579664 | I5: 607361 | J5: 631551 | K5: 654818 | L5: 680026 | M5: 707339 | N5: 735311 | O5: 762641 | P5: 788980 | Q5: 815548 | R5: 842105 | S5: 866529 | T5: 888970 | U5: 912349 | V5: 936579 | W5: 961035 | X5: 986460 | Y5: 1011913 | Z5: 1035864 | AA5: 1056933 | AB5: 1073044 | AC5: 1082289 | AD5: 1083958 | AE5: 1081119 | AF5: 1079118 | AG5: 1080411 | AH5: 1085029 | AI5: 1092401 | AJ5: 1102361 | AK5: 1113642 | AL5: 1124830 | AM5: 1134596 | AN5: 1141799 | AO5: 1148199 | AP5: 1155443 | AQ5: 1164451 | AR5: 1176534 | AS5: 1189412 | AT5: 1197082 | AU5: 1197292 | AV5: 1191969 | AW5: 1182585 | AX5: 1170976 | AY5: 1160995 | AZ5: 1157322 | BA5: 1160802 | BB5: 1164129 | BC5: 1160347 | BD5: 1150002 | BE5: 1138940 | BF5: 1132804 | BG5: 1132216 | BH5: 1134439 | BI5: 1137739 | BJ5: 1141281 | BK5: 1142524 | BL5: 1138138 | BM5: 1127643 | BN5: 1113195 | BO5: 1099169 | BP5: 1087894 | BQ5: 1075982 | BR5: 1058952 | BS5: 1041226 | BT5: =BS4*nSx_Mujeres!BS4 -> 1035600.4 | BU5: =BT4*nSx_Mujeres!BT4 -> 0 | BV5: =BU4*nSx_Mujeres!BU4 -> 0 | BW5: =BV4*nSx_Mujeres!BV4 -> 0 | BX5: =BW4*nSx_Mujeres!BW4 -> 0 | BY5: =BX4*nSx_Mujeres!BX4 -> 0 | BZ5: =BY4*nSx_Mujeres!BY4 -> 0 | CA5: =BZ4*nSx_Mujeres!BZ4 -> 0 | ... DN5: =DM4*nSx_Mujeres!DM4 -> 0
A6: 3 | B6: 460137 | C6: 470070 | D6: 479513 | E6: 488345 | F6: 500309 | G6: 518912 | H6: 541894 | I6: 569251 | J6: 596978 | K6: 621336 | L6: 644665 | M6: 669862 | N6: 697197 | O6: 725211 | P6: 752599 | Q6: 779107 | R6: 805816 | S6: 832439 | T6: 856870 | U6: 879391 | V6: 902343 | W6: 926792 | X6: 952212 | Y6: 978077 | Z6: 1003983 | AA6: 1028257 | AB6: 1049509 | AC6: 1065722 | AD6: 1075213 | AE6: 1077255 | AF6: 1074757 | AG6: 1073041 | AH6: 1074523 | AI6: 1079253 | AJ6: 1086660 | AK6: 1096525 | AL6: 1107594 | AM6: 1118509 | AN6: 1128019 | AO6: 1135034 | AP6: 1141279 | AQ6: 1148481 | AR6: 1157541 | AS6: 1169662 | AT6: 1182630 | AU6: 1190426 | AV6: 1190656 | AW6: 1185172 | AX6: 1175529 | AY6: 1163535 | AZ6: 1153522 | BA6: 1150700 | BB6: 1155192 | BC6: 1159369 | BD6: 1156257 | BE6: 1147211 | BF6: 1138076 | BG6: 1133618 | BH6: 1132836 | BI6: 1133899 | BJ6: 1136806 | BK6: 1139984 | BL6: 1140604 | BM6: 1135865 | BN6: 1124932 | BO6: 1109596 | BP6: 1095197 | BQ6: 1084290 | BR6: 1073059 | BS6: 1056408 | BT6: =BS5*nSx_Mujeres!BS5 -> 1040768.4 | BU6: =BT5*nSx_Mujeres!BT5 -> 0 | BV6: =BU5*nSx_Mujeres!BU5 -> 0 | BW6: =BV5*nSx_Mujeres!BV5 -> 0 | BX6: =BW5*nSx_Mujeres!BW5 -> 0 | BY6: =BX5*nSx_Mujeres!BX5 -> 0 | BZ6: =BY5*nSx_Mujeres!BY5 -> 0 | CA6: =BZ5*nSx_Mujeres!BZ5 -> 0 | ... DN6: =DM5*nSx_Mujeres!DM5 -> 0
A7: 4 | B7: 440962 | C7: 451303 | D7: 461388 | E7: 471193 | F7: 480510 | G7: 493190 | H7: 512023 | I7: 535186 | J7: 562452 | K7: 590191 | L7: 614568 | M7: 637915 | N7: 663105 | O7: 690416 | P7: 718416 | Q7: 745851 | R7: 772370 | S7: 799070 | T7: 825580 | U7: 849922 | V7: 872127 | W7: 895139 | X7: 920075 | Y7: 945729 | Z7: 971937 | AA7: 998057 | AB7: 1022348 | AC7: 1043557 | AD7: 1059948 | AE7: 1069712 | AF7: 1071972 | AG7: 1069698 | AH7: 1068149 | AI7: 1069707 | AJ7: 1074425 | AK7: 1081700 | AL7: 1091331 | AM7: 1102118 | AN7: 1112744 | AO7: 1122015 | AP7: 1128832 | AQ7: 1135023 | AR7: 1142284 | AS7: 1151367 | AT7: 1163552 | AU7: 1176595 | AV7: 1184341 | AW7: 1184363 | AX7: 1178593 | AY7: 1168568 | AZ7: 1156549 | BA7: 1147379 | BB7: 1145541 | BC7: 1150837 | BD7: 1155635 | BE7: 1153753 | BF7: 1146574 | BG7: 1139060 | BH7: 1134420 | BI7: 1132509 | BJ7: 1133180 | BK7: 1135732 | BL7: 1138318 | BM7: 1138599 | BN7: 1133449 | BO7: 1121686 | BP7: 1106027 | BQ7: 1091990 | BR7: 1081722 | BS7: 1070832 | BT7: =BS6*nSx_Mujeres!BS6 -> 1056056.7 | BU7: =BT6*nSx_Mujeres!BT6 -> 0 | BV7: =BU6*nSx_Mujeres!BU6 -> 0 | BW7: =BV6*nSx_Mujeres!BV6 -> 0 | BX7: =BW6*nSx_Mujeres!BW6 -> 0 | BY7: =BX6*nSx_Mujeres!BX6 -> 0 | BZ7: =BY6*nSx_Mujeres!BY6 -> 0 | CA7: =BZ6*nSx_Mujeres!BZ6 -> 0 | ... DN7: =DM6*nSx_Mujeres!DM6 -> 0
A8: 5 | B8: 424413 | C8: 434897 | D8: 445284 | E8: 455588 | F8: 465720 | G8: 475519 | H8: 488376 | I8: 507321 | J8: 530376 | K8: 557610 | L8: 585320 | M8: 609698 | N8: 633022 | O8: 658168 | P8: 685437 | Q8: 713422 | R8: 740795 | S8: 767265 | T8: 793809 | U8: 820148 | V8: 844219 | W8: 866403 | X8: 889660 | Y8: 914723 | Z8: 940644 | AA8: 966998 | AB8: 993055 | AC8: 1017241 | AD8: 1038585 | AE8: 1055173 | AF8: 1065069 | AG8: 1067489 | AH8: 1065353 | AI8: 1063870 | AJ8: 1065406 | AK8: 1069985 | AL8: 1077029 | AM8: 1086385 | AN8: 1096873 | AO8: 1107248 | AP8: 1116291 | AQ8: 1123037 | AR8: 1129280 | AS8: 1136561 | AT8: 1145715 | AU8: 1157964 | AV8: 1170928 | AW8: 1178433 | AX8: 1178152 | AY8: 1171989 | AZ8: 1161935 | BA8: 1150737 | BB8: 1142538 | BC8: 1141496 | BD8: 1147391 | BE8: 1153356 | BF8: 1153268 | BG8: 1147654 | BH8: 1139964 | BI8: 1134231 | BJ8: 1131936 | BK8: 1132265 | BL8: 1134251 | BM8: 1136519 | BN8: 1136414 | BO8: 1130490 | BP8: 1118428 | BQ8: 1103121 | BR8: 1089693 | BS8: 1079737 | BT8: =BS7*nSx_Mujeres!BS7 -> 1070538.2 | BU8: =BT7*nSx_Mujeres!BT7 -> 0 | BV8: =BU7*nSx_Mujeres!BU7 -> 0 | BW8: =BV7*nSx_Mujeres!BV7 -> 0 | BX8: =BW7*nSx_Mujeres!BW7 -> 0 | BY8: =BX7*nSx_Mujeres!BX7 -> 0 | BZ8: =BY7*nSx_Mujeres!BY7 -> 0 | CA8: =BZ7*nSx_Mujeres!BZ7 -> 0 | ... DN8: =DM7*nSx_Mujeres!DM7 -> 0
A9: 6 | B9: 408383 | C9: 420070 | D9: 430543 | E9: 441059 | F9: 451587 | G9: 462026 | H9: 471946 | I9: 484891 | J9: 503733 | K9: 526757 | L9: 553956 | M9: 581638 | N9: 605968 | O9: 629239 | P9: 654339 | Q9: 681565 | R9: 709451 | S9: 736747 | T9: 763045 | U9: 789390 | V9: 815484 | W9: 839474 | X9: 861761 | Y9: 885088 | Z9: 910354 | AA9: 936372 | AB9: 962637 | AC9: 988559 | AD9: 1012840 | AE9: 1034329 | AF9: 1050996 | AG9: 1060989 | AH9: 1063511 | AI9: 1061433 | AJ9: 1059928 | AK9: 1061323 | AL9: 1065681 | AM9: 1072458 | AN9: 1081523 | AO9: 1091762 | AP9: 1101892 | AQ9: 1110855 | AR9: 1117647 | AS9: 1123915 | AT9: 1131264 | AU9: 1140491 | AV9: 1152663 | AW9: 1165367 | AX9: 1172544 | AY9: 1171862 | AZ9: 1165660 | BA9: 1156391 | BB9: 1146140 | BC9: 1138725 | BD9: 1138283 | BE9: 1145306 | BF9: 1152986 | BG9: 1154406 | BH9: 1148622 | BI9: 1139880 | BJ9: 1133764 | BK9: 1131138 | BL9: 1130932 | BM9: 1132622 | BN9: 1134533 | BO9: 1133697 | BP9: 1127487 | BQ9: 1115757 | BR9: 1101034 | BS9: 1087909 | BT9: =BS8*nSx_Mujeres!BS8 -> 1079478.5 | BU9: =BT8*nSx_Mujeres!BT8 -> 0 | BV9: =BU8*nSx_Mujeres!BU8 -> 0 | BW9: =BV8*nSx_Mujeres!BV8 -> 0 | BX9: =BW8*nSx_Mujeres!BW8 -> 0 | BY9: =BX8*nSx_Mujeres!BX8 -> 0 | BZ9: =BY8*nSx_Mujeres!BY8 -> 0 | CA9: =BZ8*nSx_Mujeres!BZ8 -> 0 | ... DN9: =DM8*nSx_Mujeres!DM8 -> 0
A10: 7 | B10: 392893 | C10: 405145 | D10: 416781 | E10: 427328 | F10: 438000 | G10: 448729 | H10: 459235 | I10: 469212 | J10: 482076 | K10: 500894 | L10: 523899 | M10: 551068 | N10: 578678 | O10: 602938 | P10: 626162 | Q10: 651213 | R10: 678329 | S10: 706123 | T10: 733237 | U10: 759328 | V10: 785456 | W10: 811430 | X10: 835427 | Y10: 857748 | Z10: 881232 | AA10: 906574 | AB10: 932489 | AC10: 958600 | AD10: 984590 | AE10: 1008986 | AF10: 1030517 | AG10: 1047238 | AH10: 1057288 | AI10: 1059840 | AJ10: 1057734 | AK10: 1056100 | AL10: 1057289 | AM10: 1061388 | AN10: 1067893 | AO10: 1076716 | AP10: 1086716 | AQ10: 1096763 | AR10: 1105753 | AS10: 1112560 | AT10: 1118894 | AU10: 1126320 | AV10: 1135489 | AW10: 1147421 | AX10: 1159791 | AY10: 1166555 | AZ10: 1165812 | BA10: 1160355 | BB10: 1151986 | BC10: 1142502 | BD10: 1135697 | BE10: 1136352 | BF10: 1145013 | BG10: 1154140 | BH10: 1155401 | BI10: 1148599 | BJ10: 1139485 | BK10: 1133057 | BL10: 1129921 | BM10: 1129435 | BN10: 1130793 | BO10: 1132024 | BP10: 1130920 | BQ10: 1125020 | BR10: 1113834 | BS10: 1099402 | BT10: =BS9*nSx_Mujeres!BS9 -> 1087669.8 | BU10: =BT9*nSx_Mujeres!BT9 -> 0 | BV10: =BU9*nSx_Mujeres!BU9 -> 0 | BW10: =BV9*nSx_Mujeres!BV9 -> 0 | BX10: =BW9*nSx_Mujeres!BW9 -> 0 | BY10: =BX9*nSx_Mujeres!BX9 -> 0 | BZ10: =BY9*nSx_Mujeres!BY9 -> 0 | CA10: =BZ9*nSx_Mujeres!BZ9 -> 0 | ... DN10: =DM9*nSx_Mujeres!DM9 -> 0
A11: 8 | B11: 379793 | C11: 390389 | D11: 402573 | E11: 414240 | F11: 424896 | G11: 435702 | H11: 446468 | I11: 456996 | J11: 466901 | K11: 479758 | L11: 498568 | M11: 521558 | N11: 548656 | O11: 576177 | P11: 600381 | Q11: 623553 | R11: 648496 | S11: 675517 | T11: 703131 | U11: 730037 | V11: 755930 | W11: 781929 | X11: 807857 | Y11: 831843 | Z11: 854280 | AA11: 877824 | AB11: 903058 | AC11: 928822 | AD11: 954981 | AE11: 981064 | AF11: 1005473 | AG11: 1027033 | AH11: 1043770 | AI11: 1053824 | AJ11: 1056339 | AK11: 1054105 | AL11: 1052275 | AM11: 1053220 | AN11: 1057063 | AO11: 1063339 | AP11: 1071938 | AQ11: 1081851 | AR11: 1091914 | AS11: 1100909 | AT11: 1107783 | AU11: 1114192 | AV11: 1121568 | AW11: 1130526 | AX11: 1142148 | AY11: 1154102 | AZ11: 1160777 | BA11: 1160726 | BB11: 1156126 | BC11: 1148497 | BD11: 1139613 | BE11: 1133879 | BF11: 1136112 | BG11: 1146153 | BH11: 1155132 | BI11: 1155418 | BJ11: 1148257 | BK11: 1138838 | BL11: 1131918 | BM11: 1128524 | BN11: 1127736 | BO11: 1128455 | BP11: 1129439 | BQ11: 1128626 | BR11: 1123228 | BS11: 1112323 | BT11: =BS10*nSx_Mujeres!BS10 -> 1099167.9 | BU11: =BT10*nSx_Mujeres!BT10 -> 0 | BV11: =BU10*nSx_Mujeres!BU10 -> 0 | BW11: =BV10*nSx_Mujeres!BV10 -> 0 | BX11: =BW10*nSx_Mujeres!BW10 -> 0 | BY11: =BX10*nSx_Mujeres!BX10 -> 0 | BZ11: =BY10*nSx_Mujeres!BY10 -> 0 | CA11: =BZ10*nSx_Mujeres!BZ10 -> 0 | ... DN11: =DM10*nSx_Mujeres!DM10 -> 0
A12: 9 | B12: 367676 | C12: 377774 | D12: 388307 | E12: 400498 | F12: 412236 | G12: 422983 | H12: 433809 | I12: 444576 | J12: 455029 | K12: 464929 | L12: 477795 | M12: 496601 | N12: 519537 | O12: 546550 | P12: 574003 | Q12: 598146 | R12: 621214 | S12: 646066 | T12: 672918 | U12: 700331 | V12: 727058 | W12: 752816 | X12: 778735 | Y12: 804615 | Z12: 828683 | AA12: 851159 | AB12: 874606 | AC12: 899690 | AD12: 925484 | AE12: 951725 | AF12: 977809 | AG12: 1002224 | AH12: 1023771 | AI12: 1040494 | AJ12: 1050489 | AK12: 1052863 | AL12: 1050434 | AM12: 1048375 | AN12: 1049084 | AO12: 1052714 | AP12: 1058784 | AQ12: 1067300 | AR12: 1077225 | AS12: 1087290 | AT12: 1096342 | AU12: 1103281 | AV12: 1109659 | AW12: 1116840 | AX12: 1125513 | AY12: 1136747 | AZ12: 1148598 | BA12: 1155910 | BB12: 1156666 | BC12: 1152762 | BD12: 1145713 | BE12: 1137876 | BF12: 1133667 | BG12: 1137217 | BH12: 1147117 | BI12: 1155163 | BJ12: 1155102 | BK12: 1147645 | BL12: 1137755 | BM12: 1130596 | BN12: 1126914 | BO12: 1125526 | BP12: 1126023 | BQ12: 1127278 | BR12: 1126936 | BS12: 1121806 | BT12: =BS11*nSx_Mujeres!BS11 -> 1112081.1 | BU12: =BT11*nSx_Mujeres!BT11 -> 0 | BV12: =BU11*nSx_Mujeres!BU11 -> 0 | BW12: =BV11*nSx_Mujeres!BV11 -> 0 | BX12: =BW11*nSx_Mujeres!BW11 -> 0 | BY12: =BX11*nSx_Mujeres!BX11 -> 0 | BZ12: =BY11*nSx_Mujeres!BY11 -> 0 | CA12: =BZ11*nSx_Mujeres!BZ11 -> 0 | ... DN12: =DM11*nSx_Mujeres!DM11 -> 0
A13: 10 | B13: 355298 | C13: 365985 | D13: 376021 | E13: 386557 | F13: 398794 | G13: 410590 | H13: 421348 | I13: 432164 | J13: 442858 | K13: 453298 | L13: 463209 | M13: 476087 | N13: 494855 | O13: 517723 | P13: 544673 | Q13: 572053 | R13: 596088 | S13: 619068 | T13: 643769 | U13: 670435 | V13: 697680 | W13: 724269 | X13: 749933 | Y13: 775785 | Z13: 801711 | AA13: 825791 | AB13: 848181 | AC13: 871486 | AD13: 896589 | AE13: 922457 | AF13: 948695 | AG13: 974768 | AH13: 999166 | AI13: 1020680 | AJ13: 1037328 | AK13: 1047154 | AL13: 1049317 | AM13: 1046671 | AN13: 1044392 | AO13: 1044906 | AP13: 1048346 | AQ13: 1054348 | AR13: 1062876 | AS13: 1072809 | AT13: 1082922 | AU13: 1092023 | AV13: 1098931 | AW13: 1105123 | AX13: 1112053 | AY13: 1120376 | AZ13: 1131512 | BA13: 1143950 | BB13: 1152007 | BC13: 1153420 | BD13: 1150074 | BE13: 1144039 | BF13: 1137669 | BG13: 1134721 | BH13: 1138137 | BI13: 1147146 | BJ13: 1154852 | BK13: 1154503 | BL13: 1146586 | BM13: 1136467 | BN13: 1129041 | BO13: 1124793 | BP13: 1123200 | BQ13: 1123958 | BR13: 1125660 | BS13: 1125572 | BT13: =BS12*nSx_Mujeres!BS12 -> 1121544.5 | BU13: =BT12*nSx_Mujeres!BT12 -> 0 | BV13: =BU12*nSx_Mujeres!BU12 -> 0 | BW13: =BV12*nSx_Mujeres!BV12 -> 0 | BX13: =BW12*nSx_Mujeres!BW12 -> 0 | BY13: =BX12*nSx_Mujeres!BX12 -> 0 | BZ13: =BY12*nSx_Mujeres!BY12 -> 0 | CA13: =BZ12*nSx_Mujeres!BZ12 -> 0 | ... DN13: =DM12*nSx_Mujeres!DM12 -> 0
A14: 11 | B14: 343374 | C14: 353828 | D14: 364452 | E14: 374487 | F14: 385059 | G14: 397334 | H14: 409132 | I14: 419872 | J14: 430621 | K14: 441300 | L14: 451742 | M14: 461669 | N14: 474529 | O14: 493245 | P14: 516068 | Q14: 542947 | R14: 570209 | S14: 594151 | T14: 616998 | U14: 641533 | V14: 668047 | W14: 695159 | X14: 721636 | Y14: 747225 | Z14: 773096 | AA14: 799016 | AB14: 823015 | AC14: 845271 | AD14: 868588 | AE14: 893762 | AF14: 919626 | AG14: 945845 | AH14: 971884 | AI14: 996239 | AJ14: 1017665 | AK14: 1034129 | AL14: 1043731 | AM14: 1045663 | AN14: 1042805 | AO14: 1040345 | AP14: 1040696 | AQ14: 1044073 | AR14: 1050091 | AS14: 1058631 | AT14: 1068609 | AU14: 1078768 | AV14: 1087826 | AW14: 1094564 | AX14: 1100519 | AY14: 1107123 | AZ14: 1115371 | BA14: 1127081 | BB14: 1140210 | BC14: 1148874 | BD14: 1150816 | BE14: 1148445 | BF14: 1143826 | BG14: 1138671 | BH14: 1135593 | BI14: 1138145 | BJ14: 1146819 | BK14: 1154244 | BL14: 1153445 | BM14: 1145306 | BN14: 1134937 | BO14: 1126962 | BP14: 1122523 | BQ14: 1121184 | BR14: 1122375 | BS14: 1124323 | BT14: =BS13*nSx_Mujeres!BS13 -> 1125280.4 | BU14: =BT13*nSx_Mujeres!BT13 -> 0 | BV14: =BU13*nSx_Mujeres!BU13 -> 0 | BW14: =BV13*nSx_Mujeres!BV13 -> 0 | BX14: =BW13*nSx_Mujeres!BW13 -> 0 | BY14: =BX13*nSx_Mujeres!BX13 -> 0 | BZ14: =BY13*nSx_Mujeres!BY13 -> 0 | CA14: =BZ13*nSx_Mujeres!BZ13 -> 0 | ... DN14: =DM13*nSx_Mujeres!DM13 -> 0
... A112: 109 | B112: 0 | C112: 0 | D112: 0 | E112: 0 | F112: 0 | G112: 0 | H112: 0 | I112: 0 | J112: 0 | K112: 0 | L112: 0 | M112: 0 | N112: 0 | O112: 0 | P112: 0 | Q112: 0 | R112: 0 | S112: 0 | T112: 0 | U112: 0 | V112: 0 | W112: 1 | X112: 1 | Y112: 1 | Z112: 1 | AA112: 1 | AB112: 1 | AC112: 0 | AD112: 0 | AE112: 0 | AF112: 1 | AG112: 1 | AH112: 1 | AI112: 1 | AJ112: 1 | AK112: 1 | AL112: 1 | AM112: 1 | AN112: 1 | AO112: 2 | AP112: 3 | AQ112: 2 | AR112: 3 | AS112: 3 | AT112: 4 | AU112: 4 | AV112: 3 | AW112: 4 | AX112: 4 | AY112: 5 | AZ112: 7 | BA112: 6 | BB112: 7 | BC112: 7 | BD112: 9 | BE112: 10 | BF112: 10 | BG112: 14 | BH112: 12 | BI112: 13 | BJ112: 14 | BK112: 17 | BL112: 18 | BM112: 20 | BN112: 21 | BO112: 23 | BP112: 26 | BQ112: 29 | BR112: 30 | BS112: 32 | BT112: =BS111*nSx_Mujeres!BS111 -> 21.801108 | BU112: =BT111*nSx_Mujeres!BT111 -> 0 | BV112: =BU111*nSx_Mujeres!BU111 -> 0 | BW112: =BV111*nSx_Mujeres!BV111 -> 0 | BX112: =BW111*nSx_Mujeres!BW111 -> 0 | BY112: =BX111*nSx_Mujeres!BX111 -> 0 | BZ112: =BY111*nSx_Mujeres!BY111 -> 0 | CA112: =BZ111*nSx_Mujeres!BZ111 -> 0 | ... DN112: =DM111*nSx_Mujeres!DM111 -> 0

Sheet Pob_Hombres
A1: Edad / Año | B1: 1950 | C1: 1951 | D1: 1952 | E1: 1953 | F1: 1954 | G1: 1955 | H1: 1956 | I1: 1957 | J1: 1958 | K1: 1959 | L1: 1960 | M1: 1961 | N1: 1962 | O1: 1963 | P1: 1964 | Q1: 1965 | R1: 1966 | S1: 1967 | T1: 1968 | U1: 1969 | V1: 1970 | W1: 1971 | X1: 1972 | Y1: 1973 | Z1: 1974 | AA1: 1975 | AB1: 1976 | AC1: 1977 | AD1: 1978 | AE1: 1979 | AF1: 1980 | AG1: 1981 | AH1: 1982 | AI1: 1983 | AJ1: 1984 | AK1: 1985 | AL1: 1986 | AM1: 1987 | AN1: 1988 | AO1: 1989 | AP1: 1990 | AQ1: 1991 | AR1: 1992 | AS1: 1993 | AT1: 1994 | AU1: 1995 | AV1: 1996 | AW1: 1997 | AX1: 1998 | AY1: 1999 | AZ1: 2000 | BA1: 2001 | BB1: 2002 | BC1: 2003 | BD1: 2004 | BE1: 2005 | BF1: 2006 | BG1: 2007 | BH1: 2008 | BI1: 2009 | BJ1: 2010 | BK1: 2011 | BL1: 2012 | BM1: 2013 | BN1: 2014 | BO1: 2015 | BP1: 2016 | BQ1: 2017 | BR1: 2018 | BS1: 2019 | BT1: 2020 | BU1: 2021 | BV1: 2022 | BW1: 2023 | BX1: 2024 | BY1: 2025 | BZ1: 2026 | CA1: 2027 | CB1: 2028 | CC1: 2029 | CD1: 2030 | CE1: 2031 | CF1: 2032 | CG1: 2033 | CH1: 2034 | CI1: 2035 | CJ1: 2036 | CK1: 2037 | CL1: 2038 | CM1: 2039 | CN1: 2040 | CO1: 2041 | CP1: 2042 | CQ1: 2043 | CR1: 2044 | CS1: 2045 | CT1: 2046 | CU1: 2047 | CV1: 2048 | CW1: 2049 | CX1: 2050 | CY1: 2051 | CZ1: 2052 | DA1: 2053 | DB1: 2054 | DC1: 2055 | DD1: 2056 | DE1: 2057 | DF1: 2058 | DG1: 2059 | DH1: 2060 | DI1: 2061 | DJ1: 2062 | DK1: 2063 | DL1: 2064 | DM1: 2065 | DN1: 2066 | DO1: 2067 | DP1: 2068 | DQ1: 2069 | DR1: 2070
A2: Nacimientos_mujeres | B2: =Fecundidad_quinq!B37 -> 655320.37 | C2: =Fecundidad_quinq!C37 -> 669419.56 | D2: =Fecundidad_quinq!D37 -> 688850.71 | E2: =Fecundidad_quinq!E37 -> 711987.07 | F2: =Fecundidad_quinq!F37 -> 737076.44 | G2: =Fecundidad_quinq!G37 -> 761494.83 | H2: =Fecundidad_quinq!H37 -> 783273.37 | I2: =Fecundidad_quinq!I37 -> 806115.73 | ... BS2: =Fecundidad_quinq!BS37 -> 1098901.3
A3: 0 | B3: 580871 | C3: 590635 | D3: 607681 | E3: 628132 | F3: 653135 | G3: 681057 | H3: 704873 | I3: 727988 | J3: 753757 | K3: 782328 | L3: 811492 | M3: 839600 | N3: 866509 | O3: 893470 | P3: 920256 | Q3: 944944 | R3: 967696 | S3: 991225 | T3: 1016630 | U3: 1042422 | V3: 1065503 | W3: 1088005 | X3: 1111079 | Y3: 1131239 | Z3: 1146018 | AA3: 1153502 | AB3: 1153306 | AC3: 1148387 | AD3: 1144107 | AE3: 1143502 | AF3: 1146922 | AG3: 1153492 | AH3: 1162879 | AI3: 1173891 | AJ3: 1185185 | AK3: 1195340 | AL3: 1202896 | AM3: 1209482 | AN3: 1217384 | AO3: 1226728 | AP3: 1238443 | AQ3: 1251543 | AR3: 1259330 | AS3: 1259034 | AT3: 1253104 | AU3: 1243235 | AV3: 1231406 | AW3: 1221610 | AX3: 1218166 | AY3: 1220762 | AZ3: 1222259 | BA3: 1216407 | BB3: 1203969 | BC3: 1190142 | BD3: 1179931 | BE3: 1174839 | BF3: 1175024 | BG3: 1179701 | BH3: 1185963 | BI3: 1189299 | BJ3: 1186154 | BK3: 1176579 | BL3: 1162511 | BM3: 1149416 | BN3: 1139340 | BO3: 1127238 | BP3: 1108479 | BQ3: 1088809 | BR3: 1080101 | BS3: 1078390
A4: 1 | B4: 525478 | C4: 533262 | D4: 544204 | E4: 561504 | F4: 582993 | G4: 610778 | H4: 639269 | I4: 663881 | J4: 687721 | K4: 713797 | L4: 742216 | M4: 771005 | N4: 798896 | O4: 825872 | P4: 852987 | Q4: 879903 | R4: 904717 | S4: 927538 | T4: 951184 | U4: 976796 | V4: 1001227 | W4: 1025118 | X4: 1050593 | Y4: 1074866 | Z4: 1096180 | AA4: 1112372 | AB4: 1121624 | AC4: 1123441 | AD4: 1120358 | AE4: 1117966 | AF4: 1119272 | AG4: 1124186 | AH4: 1131854 | AI4: 1142153 | AJ4: 1154025 | AK4: 1166107 | AL4: 1176887 | AM4: 1185033 | AN4: 1192321 | AO4: 1200379 | AP4: 1209972 | AQ4: 1222838 | AR4: 1236788 | AS4: 1245147 | AT4: 1245590 | AU4: 1240323 | AV4: 1230909 | AW4: 1219204 | AX4: 1209146 | AY4: 1205058 | AZ4: 1208070 | BA4: 1211354 | BB4: 1206964 | BC4: 1194957 | BD4: 1180959 | BE4: 1170941 | BF4: 1166944 | BG4: 1168497 | BH4: 1174604 | BI4: 1181933 | BJ4: 1185491 | BK4: 1182365 | BL4: 1172090 | BM4: 1157396 | BN4: 1143833 | BO4: 1132901 | BP4: 1120546 | BQ4: 1102270 | BR4: 1083364 | BS4: 1074869
A5: 2 | B5: 492568 | C5: 501972 | D5: 510723 | E5: 522494 | F5: 540544 | G5: 563849 | H5: 592164 | I5: 621112 | J5: 646183 | K5: 670383 | L5: 696536 | M5: 724851 | N5: 753636 | O5: 781733 | P5: 808985 | Q5: 836364 | R5: 863488 | S5: 888455 | T5: 911515 | U5: 935481 | V5: 960240 | W5: 985140 | X5: 1010993 | Y5: 1037234 | Z5: 1062133 | AA5: 1084014 | AB5: 1100773 | AC5: 1110581 | AD5: 1112702 | AE5: 1110024 | AF5: 1108171 | AG5: 1109799 | AH5: 1114849 | AI5: 1122636 | AJ5: 1133077 | AK5: 1145039 | AL5: 1157065 | AM5: 1167730 | AN5: 1175848 | AO5: 1183197 | AP5: 1191374 | AQ5: 1201031 | AR5: 1213882 | AS5: 1228010 | AT5: 1236713 | AU5: 1237456 | AV5: 1232302 | AW5: 1222710 | AX5: 1210506 | AY5: 1199644 | AZ5: 1195784 | BA5: 1200263 | BB5: 1204725 | BC5: 1200634 | BD5: 1188412 | BE5: 1174596 | BF5: 1165631 | BG5: 1162926 | BH5: 1165830 | BI5: 1172931 | BJ5: 1180457 | BK5: 1183991 | BL5: 1180153 | BM5: 1169238 | BN5: 1154089 | BO5: 1139736 | BP5: 1128566 | BQ5: 1116632 | BR5: 1099019 | BS5: 1080289
A6: 3 | B6: 469166 | C6: 479364 | D6: 489210 | E6: 498519 | F6: 510854 | G6: 529937 | H6: 553574 | I6: 582099 | J6: 611069 | K6: 636278 | L6: 660538 | M6: 686694 | N6: 714997 | O6: 743816 | P6: 771972 | Q6: 799306 | R6: 826689 | S6: 853778 | T6: 878691 | U6: 901737 | V6: 925185 | W6: 950084 | X6: 975855 | Y6: 1002094 | Z6: 1028737 | AA6: 1053915 | AB6: 1075921 | AC6: 1092732 | AD6: 1102652 | AE6: 1105017 | AF6: 1102625 | AG6: 1100982 | AH6: 1102719 | AI6: 1107832 | AJ6: 1115645 | AK6: 1126023 | AL6: 1137838 | AM6: 1149677 | AN6: 1160189 | AO6: 1168257 | AP6: 1175636 | AQ6: 1183867 | AR6: 1193570 | AS6: 1206563 | AT6: 1220933 | AU6: 1229801 | AV6: 1230528 | AW6: 1225121 | AX6: 1214995 | AY6: 1201996 | AZ6: 1191371 | BA6: 1188920 | BB6: 1194479 | BC6: 1199156 | BD6: 1194828 | BE6: 1182784 | BF6: 1169996 | BG6: 1162298 | BH6: 1160876 | BI6: 1164658 | BJ6: 1171884 | BK6: 1179368 | BL6: 1182216 | BM6: 1177769 | BN6: 1166433 | BO6: 1150575 | BP6: 1136034 | BQ6: 1125272 | BR6: 1113943 | BS6: 1096473
A7: 4 | B7: 450189 | C7: 460742 | D7: 471135 | E7: 481306 | F7: 491015 | G7: 504032 | H7: 523333 | I7: 547109 | J7: 575535 | K7: 604506 | L7: 629725 | M7: 654013 | N7: 680163 | O7: 708435 | P7: 737221 | Q7: 765365 | R7: 792616 | S7: 819896 | T7: 846812 | U7: 871561 | V7: 894230 | W7: 917688 | X7: 943001 | Y7: 968977 | Z7: 995503 | AA7: 1022293 | AB7: 1047430 | AC7: 1069307 | AD7: 1086138 | AE7: 1096197 | AF7: 1098719 | AG7: 1096475 | AH7: 1094924 | AI7: 1096706 | AJ7: 1101806 | AK7: 1109516 | AL7: 1119726 | AM7: 1131333 | AN7: 1142981 | AO7: 1153394 | AP7: 1161448 | AQ7: 1168870 | AR7: 1177154 | AS7: 1186994 | AT7: 1200203 | AU7: 1214679 | AV7: 1223458 | AW7: 1223897 | AX7: 1217934 | AY7: 1207029 | AZ7: 1194267 | BA7: 1185027 | BB7: 1183622 | BC7: 1189381 | BD7: 1193822 | BE7: 1189650 | BF7: 1178604 | BG7: 1167052 | BH7: 1160585 | BI7: 1159970 | BJ7: 1163839 | BK7: 1171013 | BL7: 1177846 | BM7: 1180113 | BN7: 1175268 | BO7: 1163268 | BP7: 1147258 | BQ7: 1133113 | BR7: 1122917 | BS7: 1111705
A8: 5 | B8: 433733 | C8: 444383 | D8: 455008 | E8: 465595 | F8: 476030 | G8: 486194 | H8: 499383 | I8: 518781 | J8: 542448 | K8: 570842 | L8: 599771 | M8: 625003 | N8: 649283 | O8: 675384 | P8: 703589 | Q8: 732317 | R8: 760333 | S8: 787450 | T8: 814517 | U8: 841200 | V8: 865628 | W8: 888242 | X8: 911890 | Y8: 937310 | Z8: 963499 | AA8: 990097 | AB8: 1016781 | AC8: 1041716 | AD8: 1063564 | AE8: 1080462 | AF8: 1090587 | AG8: 1093193 | AH8: 1091019 | AI8: 1089508 | AJ8: 1091272 | AK8: 1096261 | AL8: 1103800 | AM8: 1113806 | AN8: 1125211 | AO8: 1136732 | AP8: 1147103 | AQ8: 1155186 | AR8: 1162658 | AS8: 1171067 | AT8: 1181119 | AU8: 1194427 | AV8: 1208775 | AW8: 1217234 | AX8: 1217106 | AY8: 1210374 | AZ8: 1199685 | BA8: 1188271 | BB8: 1180057 | BC8: 1178889 | BD8: 1184433 | BE8: 1189016 | BF8: 1185789 | BG8: 1175932 | BH8: 1165561 | BI8: 1159843 | BJ8: 1159297 | BK8: 1163108 | BL8: 1169666 | BM8: 1175950 | BN8: 1177842 | BO8: 1172371 | BP8: 1160228 | BQ8: 1144597 | BR8: 1130991 | BS8: 1120908
A9: 6 | B9: 417557 | C9: 429534 | D9: 440191 | E9: 450930 | F9: 461697 | G9: 472423 | H9: 482708 | I9: 495983 | J9: 515278 | K9: 538924 | L9: 567271 | M9: 596181 | N9: 621388 | O9: 645613 | P9: 671641 | Q9: 699769 | R9: 728349 | S9: 756213 | T9: 783105 | U9: 809918 | V9: 836316 | W9: 860633 | X9: 883304 | Y9: 907003 | Z9: 932581 | AA9: 958803 | AB9: 985266 | AC9: 1011723 | AD9: 1036602 | AE9: 1058468 | AF9: 1075377 | AG9: 1085526 | AH9: 1088159 | AI9: 1086018 | AJ9: 1084491 | AK9: 1086143 | AL9: 1090969 | AM9: 1098318 | AN9: 1108127 | AO9: 1119401 | AP9: 1130863 | AQ9: 1141239 | AR9: 1149358 | AS9: 1156947 | AT9: 1165560 | AU9: 1175714 | AV9: 1188901 | AW9: 1202916 | AX9: 1210793 | AY9: 1209898 | AZ9: 1203363 | BA9: 1193961 | BB9: 1183547 | BC9: 1175595 | BD9: 1174271 | BE9: 1179966 | BF9: 1185435 | BG9: 1183333 | BH9: 1174602 | BI9: 1164936 | BJ9: 1159274 | BK9: 1158671 | BL9: 1161898 | BM9: 1167941 | BN9: 1173873 | BO9: 1175175 | BP9: 1169564 | BQ9: 1157778 | BR9: 1142655 | BS9: 1129168
A10: 7 | B10: 401725 | C10: 414381 | D10: 426320 | E10: 437044 | F10: 447909 | G10: 458868 | H10: 469667 | I10: 480014 | J10: 493211 | K10: 512494 | L10: 536112 | M10: 564439 | N10: 593299 | O10: 618436 | P10: 642588 | Q10: 668539 | R10: 696517 | S10: 724938 | T10: 752572 | U10: 779209 | V10: 805766 | W10: 832017 | X10: 856307 | Y10: 878985 | Z10: 902804 | AA10: 928392 | AB10: 954469 | AC10: 980709 | AD10: 1007084 | AE10: 1031967 | AF10: 1053808 | AG10: 1070689 | AH10: 1080821 | AI10: 1083456 | AJ10: 1081294 | AK10: 1079667 | AL10: 1081170 | AM10: 1085820 | AN10: 1092987 | AO10: 1102671 | AP10: 1113884 | AQ10: 1125334 | AR10: 1135725 | AS10: 1143950 | AT10: 1151735 | AU10: 1160451 | AV10: 1170504 | AW10: 1183371 | AX10: 1196807 | AY10: 1203922 | AZ10: 1203189 | BA10: 1197875 | BB10: 1189429 | BC10: 1179279 | BD10: 1171225 | BE10: 1170089 | BF10: 1176645 | BG10: 1183168 | BH10: 1182129 | BI10: 1174060 | BJ10: 1164444 | BK10: 1158718 | BL10: 1157560 | BM10: 1160309 | BN10: 1166027 | BO10: 1171404 | BP10: 1172565 | BQ10: 1167277 | BR10: 1155966 | BS10: 1140967
A11: 8 | B11: 388289 | C11: 399224 | D11: 411821 | E11: 423790 | F11: 434604 | G11: 445599 | H11: 456605 | I11: 467435 | J11: 477713 | K11: 490914 | L11: 510183 | M11: 533796 | N11: 562074 | O11: 590846 | P11: 615904 | Q11: 639981 | R11: 665791 | S11: 693612 | T11: 721808 | U11: 749190 | V11: 775591 | W11: 801986 | X11: 828153 | Y11: 852408 | Z11: 875175 | AA11: 898991 | AB11: 924437 | AC11: 950296 | AD11: 976456 | AE11: 1002822 | AF11: 1027651 | AG11: 1049433 | AH11: 1066266 | AI11: 1076369 | AJ11: 1078964 | AK11: 1076699 | AL11: 1074934 | AM11: 1076287 | AN11: 1080763 | AO11: 1087816 | AP11: 1097443 | AQ11: 1108641 | AR11: 1120100 | AS11: 1130577 | AT11: 1138984 | AU11: 1146869 | AV11: 1155492 | AW11: 1165255 | AX11: 1177580 | AY11: 1190265 | AZ11: 1197500 | BA11: 1197919 | BB11: 1193510 | BC11: 1185323 | BD11: 1175096 | BE11: 1167262 | BF11: 1166972 | BG11: 1174533 | BH11: 1182059 | BI11: 1181639 | BJ11: 1173607 | BK11: 1163926 | BL11: 1157677 | BM11: 1156068 | BN11: 1158519 | BO11: 1163721 | BP11: 1168963 | BQ11: 1170418 | BR11: 1165577 | BS11: 1154385
A12: 9 | B12: 375831 | C12: 386229 | D12: 397108 | E12: 409714 | F12: 421742 | G12: 432647 | H12: 443674 | I12: 454692 | J12: 465451 | K12: 475734 | L12: 488940 | M12: 508215 | N12: 531798 | O12: 559991 | P12: 588670 | Q12: 613646 | R12: 637592 | S12: 663257 | T12: 690866 | U12: 718818 | V12: 745977 | W12: 772213 | X12: 798490 | Y12: 824587 | Z12: 848893 | AA12: 871649 | AB12: 895334 | AC12: 920570 | AD12: 946345 | AE12: 972488 | AF12: 998795 | AG12: 1023542 | AH12: 1045249 | AI12: 1062025 | AJ12: 1072064 | AK12: 1074536 | AL12: 1072142 | AM12: 1070240 | AN12: 1071441 | AO12: 1075820 | AP12: 1082829 | AQ12: 1092438 | AR12: 1103637 | AS12: 1115174 | AT12: 1125821 | AU12: 1134317 | AV12: 1142117 | AW12: 1150473 | AX12: 1159731 | AY12: 1171353 | AZ12: 1184138 | BA12: 1192441 | BB12: 1193708 | BC12: 1189541 | BD12: 1181284 | BE12: 1171294 | BF12: 1164294 | BG12: 1164985 | BH12: 1173502 | BI12: 1181599 | BJ12: 1181207 | BK12: 1173108 | BL12: 1162925 | BM12: 1156247 | BN12: 1154366 | BO12: 1156335 | BP12: 1161417 | BQ12: 1166924 | BR12: 1168792 | BS12: 1164068
A13: 10 | B13: 363086 | C13: 374064 | D13: 384406 | E13: 395293 | F13: 407939 | G13: 420027 | H13: 430956 | I13: 441982 | J13: 452932 | K13: 463687 | L13: 473980 | M13: 487207 | N13: 506465 | O13: 529983 | P13: 558089 | Q13: 586672 | R13: 611518 | S13: 635330 | T13: 660802 | U13: 688184 | V13: 715928 | W13: 742919 | X13: 769016 | Y13: 795205 | Z13: 821315 | AA13: 845590 | AB13: 868220 | AC13: 891711 | AD13: 916861 | AE13: 942617 | AF13: 968698 | AG13: 994911 | AH13: 1019562 | AI13: 1041206 | AJ13: 1057900 | AK13: 1067787 | AL13: 1070117 | AM13: 1067588 | AN13: 1065555 | AO13: 1066670 | AP13: 1071019 | AQ13: 1078015 | AR13: 1087632 | AS13: 1098910 | AT13: 1110602 | AU13: 1121323 | AV13: 1129741 | AW13: 1137282 | AX13: 1145165 | AY13: 1153779 | AZ13: 1165507 | BA13: 1179284 | BB13: 1188372 | BC13: 1189858 | BD13: 1185625 | BE13: 1177602 | BF13: 1168424 | BG13: 1162386 | BH13: 1163990 | BI13: 1173039 | BJ13: 1181148 | BK13: 1180693 | BL13: 1172110 | BM13: 1161520 | BN13: 1154595 | BO13: 1152261 | BP13: 1154123 | BQ13: 1159445 | BR13: 1165338 | BS13: 1167324
A14: 11 | B14: 350793 | C14: 361511 | D14: 372431 | E14: 382779 | F14: 393702 | G14: 406391 | H14: 418492 | I14: 429411 | J14: 440376 | K14: 451317 | L14: 462075 | M14: 472393 | N14: 485622 | O14: 504831 | P14: 528280 | Q14: 556293 | R14: 584740 | S14: 609452 | T14: 633089 | U14: 658358 | V14: 685547 | W14: 713122 | X14: 739961 | Y14: 765956 | Z14: 792137 | AA14: 818194 | AB14: 842348 | AC14: 864796 | AD14: 888203 | AE14: 913326 | AF14: 939019 | AG14: 964994 | AH14: 991098 | AI14: 1015689 | AJ14: 1037238 | AK14: 1053757 | AL14: 1063472 | AM14: 1065647 | AN14: 1062995 | AO14: 1060904 | AP14: 1061999 | AQ14: 1066343 | AR14: 1073357 | AS14: 1083052 | AT14: 1094478 | AU14: 1106246 | AV14: 1116887 | AW14: 1125052 | AX14: 1132144 | AY14: 1139424 | AZ14: 1148157 | BA14: 1160848 | BB14: 1175355 | BC14: 1184631 | BD14: 1186045 | BE14: 1182036 | BF14: 1174798 | BG14: 1166551 | BH14: 1161384 | BI14: 1163495 | BJ14: 1172550 | BK14: 1180588 | BL14: 1179652 | BM14: 1170678 | BN14: 1159858 | BO14: 1152504 | BP14: 1150080 | BQ14: 1152162 | BR14: 1157855 | BS14: 1163876
... A112: 109 | B112: 0 | C112: 0 | D112: 0 | E112: 0 | F112: 0 | G112: 0 | H112: 0 | I112: 0 | J112: 0 | K112: 0 | L112: 0 | M112: 0 | N112: 0 | O112: 0 | P112: 0 | Q112: 0 | R112: 0 | S112: 0 | T112: 0 | U112: 0 | V112: 0 | W112: 1 | X112: 1 | Y112: 1 | Z112: 1 | AA112: 1 | AB112: 1 | AC112: 1 | AD112: 1 | AE112: 1 | AF112: 1 | AG112: 1 | AH112: 1 | AI112: 1 | AJ112: 1 | AK112: 1 | AL112: 1 | AM112: 1 | AN112: 1 | AO112: 2 | AP112: 2 | AQ112: 2 | AR112: 2 | AS112: 2 | AT112: 3 | AU112: 3 | AV112: 2 | AW112: 3 | AX112: 4 | AY112: 3 | AZ112: 3 | BA112: 4 | BB112: 4 | BC112: 4 | BD112: 5 | BE112: 5 | BF112: 6 | BG112: 6 | BH112: 8 | BI112: 8 | BJ112: 15 | BK112: 18 | BL112: 12 | BM112: 13 | BN112: 16 | BO112: 18 | BP112: 18 | BQ112: 22 | BR112: 27 | BS112: 30

Sheet nSx_Mujeres
A1: Edad / Año | B1: 1950 | C1: 1951 | D1: 1952 | E1: 1953 | F1: 1954 | G1: 1955 | H1: 1956 | I1: 1957 | J1: 1958 | K1: 1959 | L1: 1960 | M1: 1961 | N1: 1962 | O1: 1963 | P1: 1964 | Q1: 1965 | R1: 1966 | S1: 1967 | T1: 1968 | U1: 1969 | V1: 1970 | W1: 1971 | X1: 1972 | Y1: 1973 | Z1: 1974 | AA1: 1975 | AB1: 1976 | AC1: 1977 | AD1: 1978 | AE1: 1979 | AF1: 1980 | AG1: 1981 | AH1: 1982 | AI1: 1983 | AJ1: 1984 | AK1: 1985 | AL1: 1986 | AM1: 1987 | AN1: 1988 | AO1: 1989 | AP1: 1990 | AQ1: 1991 | AR1: 1992 | AS1: 1993 | AT1: 1994 | AU1: 1995 | AV1: 1996 | AW1: 1997 | AX1: 1998 | AY1: 1999 | AZ1: 2000 | BA1: 2001 | BB1: 2002 | BC1: 2003 | BD1: 2004 | BE1: 2005 | BF1: 2006 | BG1: 2007 | BH1: 2008 | BI1: 2009 | BJ1: 2010 | BK1: 2011 | BL1: 2012 | BM1: 2013 | BN1: 2014 | BO1: 2015 | BP1: 2016 | BQ1: 2017 | BR1: 2018 | BS1: 2019 | BT1: 2020 | BU1: 2021 | BV1: 2022 | BW1: 2023 | BX1: 2024 | BY1: 2025 | BZ1: 2026 | CA1: 2027 | CB1: 2028 | CC1: 2029 | CD1: 2030 | CE1: 2031 | CF1: 2032 | CG1: 2033 | CH1: 2034 | CI1: 2035 | CJ1: 2036 | CK1: 2037 | CL1: 2038 | CM1: 2039 | CN1: 2040 | CO1: 2041 | CP1: 2042 | CQ1: 2043 | CR1: 2044 | CS1: 2045 | CT1: 2046 | CU1: 2047 | CV1: 2048 | CW1: 2049 | CX1: 2050 | CY1: 2051 | CZ1: 2052 | DA1: 2053 | DB1: 2054 | DC1: 2055 | DD1: 2056 | DE1: 2057 | DF1: 2058 | DG1: 2059 | DH1: 2060 | DI1: 2061 | DJ1: 2062 | DK1: 2063 | DL1: 2064 | DM1: 2065 | DN1: 2066 | DO1: 2067 | DP1: 2068 | DQ1: 2069 | DR1: 2070
A2: Pb | B2: 0.88934732 | C2: 0.88867174 | D2: 0.89508711 | E2: 0.89297169 | F2: 0.90467865 | G2: 0.90912721 | H2: 0.91337644 | I2: 0.91704968 | J2: 0.92001114 | K2: 0.9226041 | L2: 0.92478165 | M2: 0.92677187 | N2: 0.92864055 | O2: 0.93054184 | P2: 0.932478 | Q2: 0.93433674 | R2: 0.93586512 | S2: 0.93721455 | T2: 0.93864961 | U2: 0.94035056 | V2: 0.93947138 | W2: 0.94368528 | X2: 0.9451128 | Y2: 0.94652091 | Z2: 0.94810487 | AA2: 0.94986288 | AB2: 0.95174886 | AC2: 0.95362146 | AD2: 0.95555258 | AE2: 0.95754411 | AF2: 0.95951585 | AG2: 0.96132863 | AH2: 0.96289141 | AI2: 0.96433501 | AJ2: 0.965736 | AK2: 0.96716967 | AL2: 0.96861234 | AM2: 0.97004889 | AN2: 0.97154977 | AO2: 0.97074115 | AP2: 0.97243083 | AQ2: 0.97556472 | AR2: 0.97661919 | AS2: 0.97752512 | AT2: 0.97833158 | AU2: 0.97908045 | AV2: 0.97981067 | AW2: 0.98051962 | AX2: 0.98125173 | AY2: 0.98204364 | AZ2: 0.98294104 | BA2: 0.98384549 | BB2: 0.984654 | BC2: 0.98529769 | BD2: 0.98582475 | BE2: 0.98627456 | BF2: 0.98663611 | BG2: 0.98689984 | BH2: 0.98713081 | BI2: 0.98737694 | BJ2: 0.98765942 | BK2: 0.98791392 | BL2: 0.98808167 | BM2: 0.9881739 | BN2: 0.98828326 | BO2: 0.98835651 | BP2: 0.98842403 | BQ2: 0.98839957 | BR2: 0.98853527 | BS2: 0.9887488
A3: 0 | B3: 0.9543939 | C3: 0.953101 | D3: 0.95820488 | E3: 0.95686407 | F3: 0.96331647 | G3: 0.96533206 | H3: 0.96795706 | I3: 0.96984341 | J3: 0.97151429 | K3: 0.9728682 | L3: 0.973611 | M3: 0.97452798 | N3: 0.97560169 | O3: 0.97657338 | P3: 0.97753263 | Q3: 0.97873309 | R3: 0.97967362 | S3: 0.98037505 | T3: 0.98136819 | U3: 0.98238628 | V3: 0.98135472 | W3: 0.98448068 | X3: 0.98575765 | Y3: 0.98659469 | Z3: 0.98725081 | AA3: 0.98802744 | AB3: 0.98894645 | AC3: 0.98944517 | AD3: 0.98977474 | AE3: 0.99043256 | AF3: 0.99098332 | AG3: 0.99139004 | AH3: 0.99176195 | AI3: 0.99223029 | AJ3: 0.9926378 | AK3: 0.993058 | AL3: 0.99336793 | AM3: 0.99370216 | AN3: 0.99408664 | AO3: 0.99409021 | AP3: 0.99450297 | AQ3: 0.99501203 | AR3: 0.99524831 | AS3: 0.99551869 | AT3: 0.99569002 | AU3: 0.99590793 | AV3: 0.99610688 | AW3: 0.99628768 | AX3: 0.9964627 | AY3: 0.99663712 | AZ3: 0.99682454 | BA3: 0.99702243 | BB3: 0.99720581 | BC3: 0.99733512 | BD3: 0.99744454 | BE3: 0.99754068 | BF3: 0.997584 | BG3: 0.9976406 | BH3: 0.99766587 | BI3: 0.99783791 | BJ3: 0.99786447 | BK3: 0.99791785 | BL3: 0.99793007 | BM3: 0.99793272 | BN3: 0.99793831 | BO3: 0.99795051 | BP3: 0.99796643 | BQ3: 0.997959 | BR3: 0.99798365 | BS3: 0.99801059
A4: 1 | B4: 0.95414404 | C4: 0.95183271 | D4: 0.95881412 | E4: 0.9571417 | F4: 0.96480613 | G4: 0.96672407 | H4: 0.97009026 | I4: 0.97200397 | J4: 0.97393974 | K4: 0.97545187 | L4: 0.9761764 | M4: 0.97716021 | N4: 0.97837748 | O4: 0.97944316 | P4: 0.98049369 | Q4: 0.9819455 | R4: 0.98302005 | S4: 0.98387806 | T4: 0.98495599 | U4: 0.98618216 | V4: 0.98478458 | W4: 0.98864362 | X4: 0.99018578 | Y4: 0.9912596 | Z4: 0.99201054 | AA4: 0.99280962 | AB4: 0.99367292 | AC4: 0.99402247 | AD4: 0.9941836 | AE4: 0.99469657 | AF4: 0.99509845 | AG4: 0.99535594 | AH4: 0.9955927 | AI4: 0.9959421 | AJ4: 0.99623041 | AK4: 0.99652393 | AL4: 0.99670115 | AM4: 0.99689324 | AN4: 0.99712438 | AO4: 0.99729715 | AP4: 0.997504 | AQ4: 0.99765931 | AR4: 0.99779895 | AS4: 0.99797955 | AT4: 0.99807643 | AU4: 0.99822226 | AV4: 0.9983513 | AW4: 0.99846375 | AX4: 0.99857193 | AY4: 0.99867294 | AZ4: 0.99876698 | BA4: 0.99886991 | BB4: 0.99896491 | BC4: 0.99901952 | BD4: 0.99906585 | BE4: 0.99910716 | BF4: 0.99910774 | BG4: 0.99913303 | BH4: 0.99913188 | BI4: 0.99932606 | BJ4: 0.99930295 | BK4: 0.9993316 | BL4: 0.99931808 | BM4: 0.99930766 | BN4: 0.99929464 | BO4: 0.99929831 | BP4: 0.99930904 | BQ4: 0.99930407 | BR4: 0.9993076 | BS4: 0.99930662
A5: 2 | B5: 0.97336275 | C5: 0.97137443 | D5: 0.97608872 | E5: 0.97500937 | F5: 0.98004784 | G5: 0.98085685 | H5: 0.98321564 | I5: 0.98401834 | J5: 0.98515998 | K5: 0.98604187 | L5: 0.98662118 | M5: 0.9872242 | N5: 0.98787635 | O5: 0.98847543 | P5: 0.98909146 | Q5: 0.98993007 | R5: 0.99047959 | S5: 0.99110524 | T5: 0.99148734 | U5: 0.99224738 | V5: 0.99147344 | W5: 0.99361926 | X5: 0.99431726 | Y5: 0.99509837 | Z5: 0.99569353 | AA5: 0.99615653 | AB5: 0.99645822 | AC5: 0.99667705 | AD5: 0.99692113 | AE5: 0.99714198 | AF5: 0.9973742 | AG5: 0.99758484 | AH5: 0.99774767 | AI5: 0.99787691 | AJ5: 0.99800397 | AK5: 0.99812243 | AL5: 0.99825866 | AM5: 0.99836379 | AN5: 0.99845578 | AO5: 0.99852977 | AP5: 0.99856573 | AQ5: 0.99876128 | AR5: 0.99885364 | AS5: 0.99890163 | AT5: 0.9989727 | AU5: 0.99901803 | AV5: 0.99906535 | AW5: 0.99911321 | AX5: 0.99917363 | AY5: 0.99923991 | AZ5: 0.99929506 | BA5: 0.9993466 | BB5: 0.9993836 | BC5: 0.99940701 | BD5: 0.99942145 | BE5: 0.99942986 | BF5: 0.99944946 | BG5: 0.9994559 | BH5: 0.99947091 | BI5: 0.99955602 | BJ5: 0.99953711 | BK5: 0.99955591 | BL5: 0.99955371 | BM5: 0.99955671 | BN5: 0.99955202 | BO5: 0.99955516 | BP5: 0.99956239 | BQ5: 0.99956144 | BR5: 0.99955544 | BS5: 0.99956051
A6: 3 | B6: 0.98296342 | C6: 0.98136396 | D6: 0.98459504 | E6: 0.98386891 | F6: 0.98737356 | G6: 0.98765877 | H6: 0.98937296 | I6: 0.98965762 | J6: 0.99038045 | K6: 0.99093859 | L6: 0.99142152 | M6: 0.99182528 | N6: 0.99219633 | O6: 0.99256022 | P6: 0.99295882 | Q6: 0.99348184 | R6: 0.99378468 | S6: 0.9942666 | T6: 0.99436069 | U6: 0.99488141 | V6: 0.99440919 | W6: 0.99574722 | X6: 0.99609718 | Y6: 0.99670675 | Z6: 0.99719142 | AA6: 0.99750173 | AB6: 0.99760676 | AC6: 0.99776347 | AD6: 0.99800387 | AE6: 0.99811855 | AF6: 0.99827481 | AG6: 0.99844454 | AH6: 0.99856977 | AI6: 0.99862771 | AJ6: 0.99869617 | AK6: 0.99875242 | AL6: 0.99886189 | AM6: 0.99892781 | AN6: 0.99897293 | AO6: 0.99900088 | AP6: 0.99898495 | AQ6: 0.99918348 | AR6: 0.99925233 | AS6: 0.99926011 | AT6: 0.99931574 | AU6: 0.99932948 | AV6: 0.99934949 | AW6: 0.99937434 | AX6: 0.99941511 | AY6: 0.99946482 | AZ6: 0.99950393 | BA6: 0.99953588 | BB6: 0.99955351 | BC6: 0.99956612 | BD6: 0.99957014 | BE6: 0.99956795 | BF6: 0.99959195 | BG6: 0.99959207 | BH6: 0.99961058 | BI6: 0.99965548 | BJ6: 0.99963888 | BK6: 0.99965341 | BL6: 0.99965475 | BM6: 0.99966235 | BN6: 0.99966029 | BO6: 0.99966327 | BP6: 0.99966824 | BQ6: 0.99966908 | BR6: 0.99966112 | BS6: 0.99966745
A7: 4 | B7: 0.98842022 | C7: 0.98714436 | D7: 0.98941695 | E7: 0.9889103 | F7: 0.99144933 | G7: 0.99147814 | H7: 0.99276649 | I7: 0.99279773 | J7: 0.99327952 | K7: 0.99365455 | L7: 0.99405903 | M7: 0.99434776 | N7: 0.99456586 | O7: 0.99479772 | P7: 0.99507381 | Q7: 0.9954178 | R7: 0.99559123 | S7: 0.99597523 | T7: 0.99593687 | U7: 0.99631672 | V7: 0.99600973 | W7: 0.99690482 | X7: 0.99708137 | Y7: 0.99757682 | Z7: 0.9979799 | AA7: 0.99820653 | AB7: 0.99822542 | AC7: 0.99834096 | AD7: 0.99856242 | AE7: 0.99862695 | AF7: 0.99873967 | AG7: 0.99887773 | AH7: 0.99897978 | AI7: 0.99901091 | AJ7: 0.99905179 | AK7: 0.99907941 | AL7: 0.99916999 | AM7: 0.99921233 | AN7: 0.99923655 | AO7: 0.99923823 | AP7: 0.99920211 | AQ7: 0.9993965 | AR7: 0.99945246 | AS7: 0.99944592 | AT7: 0.99949048 | AU7: 0.99949171 | AV7: 0.99949985 | AW7: 0.99951395 | AX7: 0.99954396 | AY7: 0.99958387 | AZ7: 0.99961438 | BA7: 0.99963623 | BB7: 0.99964478 | BC7: 0.99965207 | BD7: 0.99965193 | BE7: 0.99964551 | BF7: 0.99967038 | BG7: 0.99966759 | BH7: 0.99968648 | BI7: 0.99971062 | BJ7: 0.99969588 | BK7: 0.99970818 | BL7: 0.99971098 | BM7: 0.99972051 | BN7: 0.99971937 | BO7: 0.99972288 | BP7: 0.99972569 | BQ7: 0.99972705 | BR7: 0.99971904 | BS7: 0.9997256
A8: 5 | B8: 0.99177087 | C8: 0.99075076 | D8: 0.99238635 | E8: 0.99202365 | F8: 0.99391793 | G8: 0.99382395 | H8: 0.99481738 | I8: 0.99472269 | J8: 0.99505705 | K8: 0.99532021 | L8: 0.9956611 | M8: 0.99587807 | N8: 0.99600782 | O8: 0.9961594 | P8: 0.99636157 | Q8: 0.99659543 | R8: 0.99669535 | S8: 0.99700942 | T8: 0.99690742 | U8: 0.99719558 | V8: 0.99698838 | W8: 0.99761637 | X8: 0.99769556 | Y8: 0.99810871 | Z8: 0.99844754 | AA8: 0.99862428 | AB8: 0.99860264 | AC8: 0.99868499 | AD8: 0.99888578 | AE8: 0.99892387 | AF8: 0.99900918 | AG8: 0.99912206 | AH8: 0.99920932 | AI8: 0.99923153 | AJ8: 0.99925798 | AK8: 0.99927046 | AL8: 0.9993467 | AM8: 0.99937291 | AN8: 0.99938727 | AO8: 0.99937298 | AP8: 0.99932925 | AQ8: 0.99951644 | AR8: 0.99956459 | AS8: 0.99955528 | AT8: 0.99958968 | AU8: 0.99958791 | AV8: 0.99959021 | AW8: 0.99959835 | AX8: 0.99962238 | AY8: 0.99965532 | AZ8: 0.99968036 | BA8: 0.99969615 | BB8: 0.99970027 | BC8: 0.99970404 | BD8: 0.99970261 | BE8: 0.99969428 | BF8: 0.99971863 | BG8: 0.99971415 | BH8: 0.99973212 | BI8: 0.9997432 | BJ8: 0.99973123 | BK8: 0.99974158 | BL8: 0.99974532 | BM8: 0.99975591 | BN8: 0.99975433 | BO8: 0.99975842 | BP8: 0.99975998 | BQ8: 0.99975975 | BR8: 0.99975301 | BS8: 0.99976055
A9: 6 | B9: 0.993931 | C9: 0.99311105 | D9: 0.99431209 | E9: 0.99405045 | F9: 0.9954926 | G9: 0.9953497 | H9: 0.99612822 | I9: 0.99597704 | J9: 0.99621661 | K9: 0.99640849 | L9: 0.99669678 | M9: 0.99686676 | N9: 0.99694262 | O9: 0.99704433 | P9: 0.99720026 | Q9: 0.99736224 | R9: 0.99741759 | S9: 0.99767938 | T9: 0.99754912 | U9: 0.99777395 | V9: 0.99763064 | W9: 0.99808594 | X9: 0.9981064 | Y9: 0.99845521 | Z9: 0.99874113 | AA9: 0.99888661 | AB9: 0.99884762 | AC9: 0.99890128 | AD9: 0.99908227 | AE9: 0.99910661 | AF9: 0.99917317 | AG9: 0.99926586 | AH9: 0.99934352 | AI9: 0.99936523 | AJ9: 0.99938398 | AK9: 0.9993868 | AL9: 0.99945248 | AM9: 0.99946842 | AN9: 0.99947741 | AO9: 0.99945342 | AP9: 0.99940776 | AQ9: 0.99958622 | AR9: 0.99962914 | AS9: 0.99962237 | AT9: 0.99964731 | AU9: 0.99964728 | AV9: 0.9996471 | AW9: 0.99965303 | AX9: 0.99967216 | AY9: 0.99969945 | AZ9: 0.99972124 | BA9: 0.99973326 | BB9: 0.99973457 | BC9: 0.99973656 | BD9: 0.99973575 | BE9: 0.99972616 | BF9: 0.99974898 | BG9: 0.99974316 | BH9: 0.99975912 | BI9: 0.99976055 | BJ9: 0.99975235 | BK9: 0.99976153 | BL9: 0.99976605 | BM9: 0.99977767 | BN9: 0.99977314 | BO9: 0.99977847 | BP9: 0.9997795 | BQ9: 0.99977553 | BR9: 0.99977154 | BS9: 0.99978009
A10: 7 | B10: 0.99536141 | C10: 0.99470089 | D10: 0.99559701 | E10: 0.995411 | F10: 0.99652449 | G10: 0.99637573 | H10: 0.99699356 | I10: 0.99682402 | J10: 0.99700063 | K10: 0.99714778 | L10: 0.99739086 | M10: 0.99752928 | N10: 0.99757186 | O10: 0.9976427 | P10: 0.99776913 | Q10: 0.99788313 | R10: 0.99791054 | S10: 0.99813034 | T10: 0.99799227 | U10: 0.99817107 | V10: 0.99807053 | W10: 0.99840888 | X10: 0.99839239 | Y10: 0.99868712 | Z10: 0.99892762 | AA10: 0.99905437 | AB10: 0.99900997 | AC10: 0.99903805 | AD10: 0.99920236 | AE10: 0.9992195 | AF10: 0.99927281 | AG10: 0.99935015 | AH10: 0.99942111 | AI10: 0.99944622 | AJ10: 0.99946091 | AK10: 0.99945804 | AL10: 0.99951571 | AM10: 0.9995254 | AN10: 0.99953055 | AO10: 0.99950212 | AP10: 0.99945641 | AQ10: 0.99962515 | AR10: 0.99966523 | AS10: 0.99966265 | AT10: 0.99967945 | AU10: 0.99968233 | AV10: 0.99968157 | AW10: 0.99968846 | AX10: 0.99970299 | AY10: 0.99972603 | AZ10: 0.99974517 | BA10: 0.99975445 | BB10: 0.99975436 | BC10: 0.99975471 | BD10: 0.99975653 | BE10: 0.99974588 | BF10: 0.99976683 | BG10: 0.99975921 | BH10: 0.99977281 | BI10: 0.99976565 | BJ10: 0.99976049 | BK10: 0.99976982 | BL10: 0.99977543 | BM10: 0.99978788 | BN10: 0.99977864 | BO10: 0.99978635 | BP10: 0.99978678 | BQ10: 0.99977728 | BR10: 0.99977741 | BS10: 0.99978706
A11: 8 | B11: 0.99631312 | C11: 0.99578171 | D11: 0.9964589 | E11: 0.99633635 | F11: 0.99720278 | G11: 0.99707452 | H11: 0.99756925 | I11: 0.99740421 | J11: 0.99753793 | K11: 0.99765791 | L11: 0.99786248 | M11: 0.99798014 | N11: 0.99800227 | O11: 0.99805468 | P11: 0.99816337 | Q11: 0.99824465 | R11: 0.99825284 | S11: 0.99843913 | T11: 0.99830511 | U11: 0.99844865 | V11: 0.9983786 | W11: 0.99863432 | X11: 0.99859314 | Y11: 0.99884059 | Z11: 0.99904206 | AA11: 0.99915883 | AB11: 0.9991156 | AC11: 0.99912146 | AD11: 0.9992721 | AE11: 0.99928557 | AF11: 0.99932989 | AG11: 0.9993962 | AH11: 0.99946243 | AI11: 0.99949218 | AJ11: 0.99950558 | AK11: 0.99949894 | AL11: 0.99955116 | AM11: 0.9995576 | AN11: 0.99955999 | AO11: 0.99953042 | AP11: 0.99948629 | AQ11: 0.99964368 | AR11: 0.99968244 | AS11: 0.99968431 | AT11: 0.99969428 | AU11: 0.99969973 | AV11: 0.99969934 | AW11: 0.99970908 | AX11: 0.99971917 | AY11: 0.99973858 | AZ11: 0.99975538 | BA11: 0.99976218 | BB11: 0.99976222 | BC11: 0.99976059 | BD11: 0.99976636 | BE11: 0.99975528 | BF11: 0.99977357 | BG11: 0.99976397 | BH11: 0.99977459 | BI11: 0.99975983 | BJ11: 0.99975649 | BK11: 0.99976606 | BL11: 0.99977269 | BM11: 0.99978711 | BN11: 0.99977205 | BO11: 0.99978218 | BP11: 0.99978232 | BQ11: 0.99976686 | BR11: 0.99977205 | BS11: 0.99978251
A12: 9 | B12: 0.99693228 | C12: 0.996505 | D12: 0.99702465 | E12: 0.9969606 | F12: 0.99763552 | G12: 0.99754509 | H12: 0.99794365 | I12: 0.99779628 | J12: 0.99790243 | K12: 0.9980052 | L12: 0.9981767 | M12: 0.9982829 | N12: 0.99829181 | O12: 0.9983356 | P12: 0.99843612 | Q12: 0.99849243 | R12: 0.99848821 | S12: 0.99864703 | T12: 0.99852662 | U12: 0.99864055 | V12: 0.99859407 | W12: 0.99879007 | X12: 0.99873077 | Y12: 0.99893628 | Z12: 0.99910525 | AA12: 0.99921702 | AB12: 0.99917933 | AC12: 0.99916723 | AD12: 0.99930612 | AE12: 0.99931902 | AF12: 0.99935771 | AG12: 0.99941601 | AH12: 0.99947865 | AI12: 0.99951404 | AJ12: 0.99952741 | AK12: 0.99951823 | AL12: 0.99956719 | AM12: 0.9995729 | AN12: 0.99957306 | AO12: 0.99954484 | AP12: 0.99950327 | AQ12: 0.99964845 | AR12: 0.99968604 | AS12: 0.99969173 | AT12: 0.99969672 | AU12: 0.99970304 | AV12: 0.99970347 | AW12: 0.99971696 | AX12: 0.99972295 | AY12: 0.99973907 | AZ12: 0.99975397 | BA12: 0.99975869 | BB12: 0.99975919 | BC12: 0.99975591 | BD12: 0.99976656 | BE12: 0.99975507 | BF12: 0.99976977 | BG12: 0.99975882 | BH12: 0.99976545 | BI12: 0.99974417 | BJ12: 0.99973986 | BK12: 0.99974987 | BL12: 0.99975711 | BM12: 0.99977509 | BN12: 0.99975403 | BO12: 0.99976672 | BP12: 0.99976616 | BQ12: 0.99974549 | BR12: 0.99975542 | BS12: 0.99976689
A13: 10 | B13: 0.99730924 | C13: 0.99696483 | D13: 0.99737455 | E13: 0.9973633 | F13: 0.99789108 | G13: 0.99784669 | H13: 0.99816891 | I13: 0.9980467 | J13: 0.99813679 | K13: 0.99823091 | L13: 0.99837368 | M13: 0.99847517 | N13: 0.99847582 | O13: 0.99851802 | P13: 0.99861698 | Q13: 0.99865544 | R13: 0.99864321 | S13: 0.99877937 | T13: 0.99867831 | U13: 0.99876702 | V13: 0.99873968 | W13: 0.99889106 | X13: 0.9988189 | Y13: 0.99898701 | Z13: 0.99913051 | AA13: 0.99923964 | AB13: 0.99921058 | AC13: 0.99918547 | AD13: 0.99931359 | AE13: 0.99932849 | AF13: 0.99936432 | AG13: 0.99941697 | AH13: 0.999477 | AI13: 0.99951817 | AJ13: 0.99953246 | AK13: 0.99952203 | AL13: 0.99956866 | AM13: 0.99957521 | AN13: 0.99957416 | AO13: 0.99954932 | AP13: 0.99951043 | AQ13: 0.9996431 | AR13: 0.99967962 | AS13: 0.99968802 | AT13: 0.99969 | AU13: 0.99969505 | AV13: 0.99969637 | AW13: 0.99971316 | AX13: 0.99971618 | AY13: 0.99972929 | AZ13: 0.99974273 | BA13: 0.99974501 | BB13: 0.99974608 | BC13: 0.99974201 | BD13: 0.99975708 | BE13: 0.9997453 | BF13: 0.99975636 | BG13: 0.99974492 | BH13: 0.99974757 | BI13: 0.99972081 | BJ13: 0.99971019 | BK13: 0.99972153 | BL13: 0.99972879 | BM13: 0.9997516 | BN13: 0.99972579 | BO13: 0.99974114 | BP13: 0.99973909 | BQ13: 0.99971452 | BR13: 0.99972911 | BS13: 0.9997409
A14: 11 | B14: 0.99750439 | C14: 0.99722592 | D14: 0.99755992 | E14: 0.99759598 | F14: 0.99801342 | G14: 0.99801707 | H14: 0.9982792 | I14: 0.99818743 | J14: 0.99826838 | K14: 0.9983614 | L14: 0.99847954 | M14: 0.99858026 | N14: 0.99857755 | O14: 0.99862212 | P14: 0.99872464 | Q14: 0.99875046 | R14: 0.99873387 | S14: 0.99885107 | T14: 0.99877169 | U14: 0.99884157 | V14: 0.99882876 | W14: 0.99894718 | X14: 0.9988661 | Y14: 0.99900067 | Z14: 0.99912589 | AA14: 0.9992343 | AB14: 0.999216 | AC14: 0.99918185 | AD14: 0.99930169 | AE14: 0.99931927 | AF14: 0.99935445 | AG14: 0.99940358 | AH14: 0.99946211 | AI14: 0.99950848 | AJ14: 0.99952514 | AK14: 0.99951339 | AL14: 0.99955946 | AM14: 0.99956858 | AN14: 0.99956643 | AO14: 0.99954605 | AP14: 0.99950994 | AQ14: 0.99963042 | AR14: 0.99966651 | AS14: 0.99967498 | AT14: 0.99967641 | AU14: 0.99967804 | AV14: 0.99968044 | AW14: 0.99969881 | AX14: 0.99969961 | AY14: 0.99971126 | AZ14: 0.99972309 | BA14: 0.99972293 | BB14: 0.99972429 | BC14: 0.99972046 | BD14: 0.99973795 | BE14: 0.99972628 | BF14: 0.99973479 | BG14: 0.9997233 | BH14: 0.99972271 | BI14: 0.99969128 | BJ14: 0.99966905 | BK14: 0.99968177 | BL14: 0.9996879 | BM14: 0.99971805 | BN14: 0.99968898 | BO14: 0.99970627 | BP14: 0.99970236 | BQ14: 0.99967574 | BR14: 0.99969449 | BS14: 0.99970519
... A111: 108 | B111: 0.34753081 | C111: 0.34728544 | D111: 0.34778249 | E111: 0.34778249 | F111: 0.3488555 | G111: 0.34912154 | H111: 0.34942939 | I111: 0.34942939 | J111: 0.34975376 | K111: 0.35008204 | L111: 0.35008204 | M111: 0.35077591 | N111: 0.35077591 | O111: 0.35077591 | P111: 0.35113564 | Q111: 0.35152129 | R111: 0.35152129 | S111: 0.35191514 | T111: 0.35191514 | U111: 0.35233121 | V111: 0.35191514 | W111: 0.35277078 | X111: 0.35322187 | Y111: 0.35322187 | Z111: 0.35422073 | AA111: 0.35422073 | AB111: 0.35476102 | AC111: 0.35476102 | AD111: 0.3553429 | AE111: 0.3553429 | AF111: 0.3559447 | AG111: 0.3559447 | AH111: 0.35677123 | AI111: 0.35677123 | AJ111: 0.3576572 | AK111: 0.3576572 | AL111: 0.3588157 | AM111: 0.3588157 | AN111: 0.3588157 | AO111: 0.3588157 | AP111: 0.36048186 | AQ111: 0.36048186 | AR111: 0.36220461 | AS111: 0.36220461 | AT111: 0.36220461 | AU111: 0.36220461 | AV111: 0.36220461 | AW111: 0.36220461 | AX111: 0.36443543 | AY111: 0.36443543 | AZ111: 0.36682418 | BA111: 0.36682418 | BB111: 0.36682418 | BC111: 0.36682418 | BD111: 0.36682418 | BE111: 0.36682418 | BF111: 0.36951031 | BG111: 0.36682418 | BH111: 0.36682418 | BI111: 0.36682418 | BJ111: 0.36682418 | BK111: 0.36951031 | BL111: 0.36951031 | BM111: 0.36951031 | BN111: 0.36951031 | BO111: 0.36951031 | BP111: 0.36951031 | BQ111: 0.36951031 | BR111: 0.36951031 | BS111: 0.36951031

Sheet nSx_Hombres
A1: Edad / Año | B1: 1950 | C1: 1951 | D1: 1952 | E1: 1953 | F1: 1954 | G1: 1955 | H1: 1956 | I1: 1957 | J1: 1958 | K1: 1959 | L1: 1960 | M1: 1961 | N1: 1962 | O1: 1963 | P1: 1964 | Q1: 1965 | R1: 1966 | S1: 1967 | T1: 1968 | U1: 1969 | V1: 1970 | W1: 1971 | X1: 1972 | Y1: 1973 | Z1: 1974 | AA1: 1975 | AB1: 1976 | AC1: 1977 | AD1: 1978 | AE1: 1979 | AF1: 1980 | AG1: 1981 | AH1: 1982 | AI1: 1983 | AJ1: 1984 | AK1: 1985 | AL1: 1986 | AM1: 1987 | AN1: 1988 | AO1: 1989 | AP1: 1990 | AQ1: 1991 | AR1: 1992 | AS1: 1993 | AT1: 1994 | AU1: 1995 | AV1: 1996 | AW1: 1997 | AX1: 1998 | AY1: 1999 | AZ1: 2000 | BA1: 2001 | BB1: 2002 | BC1: 2003 | BD1: 2004 | BE1: 2005 | BF1: 2006 | BG1: 2007 | BH1: 2008 | BI1: 2009 | BJ1: 2010 | BK1: 2011 | BL1: 2012 | BM1: 2013 | BN1: 2014 | BO1: 2015 | BP1: 2016 | BQ1: 2017 | BR1: 2018 | BS1: 2019 | BT1: 2020 | BU1: 2021 | BV1: 2022 | BW1: 2023 | BX1: 2024 | BY1: 2025 | BZ1: 2026 | CA1: 2027 | CB1: 2028 | CC1: 2029 | CD1: 2030 | CE1: 2031 | CF1: 2032 | CG1: 2033 | CH1: 2034 | CI1: 2035 | CJ1: 2036 | CK1: 2037 | CL1: 2038 | CM1: 2039 | CN1: 2040 | CO1: 2041 | CP1: 2042 | CQ1: 2043 | CR1: 2044 | CS1: 2045 | CT1: 2046 | CU1: 2047 | CV1: 2048 | CW1: 2049 | CX1: 2050 | CY1: 2051 | CZ1: 2052 | DA1: 2053 | DB1: 2054 | DC1: 2055 | DD1: 2056 | DE1: 2057 | DF1: 2058 | DG1: 2059 | DH1: 2060 | DI1: 2061 | DJ1: 2062 | DK1: 2063 | DL1: 2064 | DM1: 2065 | DN1: 2066 | DO1: 2067 | DP1: 2068 | DQ1: 2069 | DR1: 2070
A2: Pb | B2: 0.87303173 | C2: 0.87209888 | D2: 0.87920612 | E2: 0.87665656 | F2: 0.88983082 | G2: 0.89484381 | H2: 0.89957761 | I2: 0.90366576 | J2: 0.90694358 | K2: 0.90980348 | L2: 0.91218619 | M2: 0.91435583 | N2: 0.9163906 | O2: 0.91846994 | P2: 0.9205964 | Q2: 0.92263779 | R2: 0.92429884 | S2: 0.92575498 | T2: 0.92731644 | U2: 0.92919843 | V2: 0.92804075 | W2: 0.93288903 | X2: 0.93448072 | Y2: 0.93604114 | Z2: 0.93781632 | AA2: 0.93980653 | AB2: 0.94195977 | AC2: 0.94410748 | AD2: 0.94633405 | AE2: 0.94864431 | AF2: 0.95094325 | AG2: 0.95306048 | AH2: 0.95488506 | AI2: 0.95657378 | AJ2: 0.95821917 | AK2: 0.95991353 | AL2: 0.96162578 | AM2: 0.96334024 | AN2: 0.96513923 | AO2: 0.96412563 | AP2: 0.96615854 | AQ2: 0.96997408 | AR2: 0.97125313 | AS2: 0.97234758 | AT2: 0.97332415 | AU2: 0.97423137 | AV2: 0.97511695 | AW2: 0.97597934 | AX2: 0.97687035 | AY2: 0.97783494 | AZ2: 0.97894011 | BA2: 0.98005754 | BB2: 0.98105434 | BC2: 0.98184532 | BD2: 0.98249027 | BE2: 0.98303855 | BF2: 0.98348067 | BG2: 0.98380854 | BH2: 0.98411179 | BI2: 0.98443882 | BJ2: 0.98480025 | BK2: 0.98512681 | BL2: 0.98534479 | BM2: 0.98547241 | BN2: 0.98562336 | BO2: 0.98573365 | BP2: 0.98583663 | BQ2: 0.98582788 | BR2: 0.98601458 | BS2: 0.98629426
A3: 0 | B3: 0.95171421 | C3: 0.95077507 | D3: 0.95610638 | E3: 0.95464267 | F3: 0.9611842 | G3: 0.96374135 | H3: 0.96598038 | I3: 0.96805827 | J3: 0.96977231 | K3: 0.97106281 | L3: 0.97200863 | M3: 0.97278642 | N3: 0.97381843 | O3: 0.97489107 | P3: 0.97597155 | Q3: 0.97697211 | R3: 0.97790435 | S3: 0.97863469 | T3: 0.9796806 | U3: 0.98062898 | V3: 0.97947647 | W3: 0.98266001 | X3: 0.98392734 | Y3: 0.98466739 | Z3: 0.98556809 | AA3: 0.98631178 | AB3: 0.98734511 | AC3: 0.98805293 | AD3: 0.98846343 | AE3: 0.98914907 | AF3: 0.98980035 | AG3: 0.99026472 | AH3: 0.99066675 | AI3: 0.99107607 | AJ3: 0.99154403 | AK3: 0.99201019 | AL3: 0.99237397 | AM3: 0.99276742 | AN3: 0.9931895 | AO3: 0.99316288 | AP3: 0.99359359 | AQ3: 0.9941642 | AR3: 0.99439291 | AS3: 0.99466371 | AT3: 0.99486574 | AU3: 0.99511108 | AV3: 0.99532595 | AW3: 0.9955158 | AX3: 0.99572091 | AY3: 0.99592055 | AZ3: 0.99614866 | BA3: 0.99638419 | BB3: 0.9965921 | BC3: 0.99674289 | BD3: 0.99686408 | BE3: 0.99696816 | BF3: 0.99704309 | BG3: 0.99709271 | BH3: 0.99715199 | BI3: 0.99733692 | BJ3: 0.99742163 | BK3: 0.99747596 | BL3: 0.99750121 | BM3: 0.99752048 | BN3: 0.99752869 | BO3: 0.99753511 | BP3: 0.99755704 | BQ3: 0.99754508 | BR3: 0.9975861 | BS3: 0.99763078
A4: 1 | B4: 0.95498572 | C4: 0.95335773 | D4: 0.96032568 | E4: 0.95856797 | F4: 0.96574541 | G4: 0.96826417 | H4: 0.97085893 | I4: 0.97287732 | J4: 0.97475594 | K4: 0.976067 | L4: 0.97700662 | M4: 0.97774496 | N4: 0.97882633 | O4: 0.97997037 | P4: 0.98110366 | Q4: 0.98219754 | R4: 0.9831828 | S4: 0.98403026 | T4: 0.98513327 | U4: 0.98618402 | V4: 0.98472219 | W4: 0.98844597 | X4: 0.98992149 | Y4: 0.99082972 | Z4: 0.99181832 | AA4: 0.99252451 | AB4: 0.99346995 | AC4: 0.99400076 | AD4: 0.99419314 | AE4: 0.99467235 | AF4: 0.99513122 | AG4: 0.99539364 | AH4: 0.9956136 | AI4: 0.99585158 | AJ4: 0.99616243 | AK4: 0.99646449 | AL4: 0.9966541 | AM4: 0.99685895 | AN4: 0.99708361 | AO4: 0.99726303 | AP4: 0.99745777 | AQ4: 0.99753911 | AR4: 0.99763523 | AS4: 0.99778882 | AT4: 0.99789022 | AU4: 0.9980406 | AV4: 0.99816261 | AW4: 0.99826843 | AX4: 0.99838305 | AY4: 0.99848316 | AZ4: 0.99859476 | BA4: 0.99870866 | BB4: 0.9988025 | BC4: 0.99886007 | BD4: 0.99890209 | BE4: 0.99893792 | BF4: 0.99895922 | BG4: 0.99896953 | BH4: 0.99899266 | BI4: 0.99919549 | BJ4: 0.99925379 | BK4: 0.99926771 | BL4: 0.99926402 | BM4: 0.99926376 | BN4: 0.99925073 | BO4: 0.99924619 | BP4: 0.99926085 | BQ4: 0.99927108 | BR4: 0.99927223 | BS4: 0.99927993
A5: 2 | B5: 0.97475694 | C5: 0.97318726 | D5: 0.97770649 | E5: 0.97651802 | F5: 0.98109558 | G5: 0.98212079 | H5: 0.98407294 | I5: 0.98484489 | J5: 0.98592702 | K5: 0.98668032 | L5: 0.98730598 | M5: 0.98783371 | N5: 0.98838913 | O5: 0.98899717 | P5: 0.98958183 | Q5: 0.99025042 | R5: 0.99069707 | S5: 0.99128129 | T5: 0.99165598 | U5: 0.99230009 | V5: 0.99156729 | W5: 0.99357039 | X5: 0.99422532 | Y5: 0.99495607 | Z5: 0.99554431 | AA5: 0.99598962 | AB5: 0.99630172 | AC5: 0.99651757 | AD5: 0.99675408 | AE5: 0.9969663 | AF5: 0.99720915 | AG5: 0.99741613 | AH5: 0.99757413 | AI5: 0.99770134 | AJ5: 0.99782677 | AK5: 0.99795272 | AL5: 0.99809089 | AM5: 0.99818743 | AN5: 0.99828466 | AO5: 0.99837464 | AP5: 0.99847049 | AQ5: 0.99860484 | AR5: 0.99870453 | AS5: 0.99876239 | AT5: 0.99883107 | AU5: 0.99887687 | AV5: 0.99892705 | AW5: 0.99899362 | AX5: 0.99905219 | AY5: 0.99911701 | AZ5: 0.99918578 | BA5: 0.99924499 | BB5: 0.99928593 | BC5: 0.99931604 | BD5: 0.99933397 | BE5: 0.99934695 | BF5: 0.99936288 | BG5: 0.99937659 | BH5: 0.99938621 | BI5: 0.99948661 | BJ5: 0.99952976 | BK5: 0.99953902 | BL5: 0.99954328 | BM5: 0.99954009 | BN5: 0.99954247 | BO5: 0.99955393 | BP5: 0.99956576 | BQ5: 0.99960725 | BR5: 0.99958022 | BS5: 0.9995824
